2021-12-20 01:19:37,158 - octoprint.startup - INFO - ******************************************************************************
2021-12-20 01:19:37,167 - octoprint.startup - INFO - Starting OctoPrint 1.3.6
2021-12-20 01:19:37,168 - octoprint.startup - INFO - ******************************************************************************
2021-12-20 01:19:37,249 - octoprint.plugin.core - INFO - Loading plugins from /opt/octoprint/venv/lib/python2.7/site-packages/OctoPrint-1.3.6-py2.7.egg/octoprint/plugins, /home/octoprint/.octoprint/plugins and installed plugin packages...
2021-12-20 01:19:37,275 - octoprint.util.connectivity_checker - INFO - Connectivity changed from offline to online
2021-12-20 01:19:38,066 - octoprint.plugin.core - WARNING - Plugin "OctoPi Support Plugin" did not pass check
2021-12-20 01:19:38,091 - octoprint.plugins.discovery - INFO - pybonjour is not installed, Zeroconf Discovery won't be available
2021-12-20 01:19:38,093 - octoprint.plugin.core - INFO - Found 7 plugin(s) providing 7 mixin implementations, 4 hook handlers
2021-12-20 01:19:38,339 - octoprint.server - INFO - Intermediary server started
2021-12-20 01:19:38,340 - octoprint.plugin.core - INFO - Loading plugins from /opt/octoprint/venv/lib/python2.7/site-packages/OctoPrint-1.3.6-py2.7.egg/octoprint/plugins, /home/octoprint/.octoprint/plugins and installed plugin packages...
2021-12-20 01:19:38,342 - octoprint.plugin.core - WARNING - Plugin "OctoPi Support Plugin" did not pass check
2021-12-20 01:19:38,359 - octoprint.plugin.core - INFO - Found 7 plugin(s) providing 7 mixin implementations, 4 hook handlers
2021-12-20 01:19:38,373 - octoprint.filemanager.storage - INFO - Initializing the file metadata for /home/octoprint/.octoprint/uploads...
2021-12-20 01:19:38,530 - octoprint.filemanager.storage - INFO - ... file metadata for /home/octoprint/.octoprint/uploads initialized successfully.
2021-12-20 01:19:38,542 - octoprint.plugins.softwareupdate - INFO - Loaded version cache from disk
2021-12-20 01:19:39,164 - octoprint.util.pip - INFO - Using "/opt/octoprint/venv/bin/python -m pip" as command to invoke pip
2021-12-20 01:19:39,553 - octoprint.util.pip - INFO - Version of pip is 9.0.1
2021-12-20 01:19:39,555 - octoprint.plugin.core - INFO - Initialized 7 plugin implementation(s)
2021-12-20 01:19:39,558 - octoprint.plugin.core - INFO - 7 plugin(s) registered with the system:
|  Announcement Plugin (bundled) = /opt/octoprint/venv/lib/python2.7/site-packages/OctoPrint-1.3.6-py2.7.egg/octoprint/plugins/announcements
|  Core Wizard (bundled) = /opt/octoprint/venv/lib/python2.7/site-packages/OctoPrint-1.3.6-py2.7.egg/octoprint/plugins/corewizard
|  CuraEngine (<= 15.04) (bundled) = /opt/octoprint/venv/lib/python2.7/site-packages/OctoPrint-1.3.6-py2.7.egg/octoprint/plugins/cura
|  Discovery (bundled) = /opt/octoprint/venv/lib/python2.7/site-packages/OctoPrint-1.3.6-py2.7.egg/octoprint/plugins/discovery
|  Plugin Manager (bundled) = /opt/octoprint/venv/lib/python2.7/site-packages/OctoPrint-1.3.6-py2.7.egg/octoprint/plugins/pluginmanager
|  Software Update (bundled) = /opt/octoprint/venv/lib/python2.7/site-packages/OctoPrint-1.3.6-py2.7.egg/octoprint/plugins/softwareupdate
|  Virtual Printer (bundled) = /opt/octoprint/venv/lib/python2.7/site-packages/OctoPrint-1.3.6-py2.7.egg/octoprint/plugins/virtual_printer
2021-12-20 01:19:39,880 - octoprint.environment - INFO - Detected environment is Python 2.7.14 under Linux (linux2). Details:
|  hardware:
|    cores: 4
|    freq: unknown
|    ram: 2082197504
|  os:
|    id: linux
|    platform: linux2
|  python:
|    pip: 9.0.1
|    version: 2.7.14
|    virtualenv: /opt/octoprint/venv
2021-12-20 01:19:39,902 - octoprint.server - INFO - Reset webasset folder /home/octoprint/.octoprint/generated/webassets...
2021-12-20 01:19:40,110 - octoprint.server - INFO - Reset webasset folder /home/octoprint/.octoprint/generated/.webassets-cache...
2021-12-20 01:19:40,194 - octoprint.server - INFO - Shutting down intermediary server...
2021-12-20 01:19:40,347 - octoprint.server - INFO - Intermediary server shut down
2021-12-20 01:19:40,349 - octoprint.events - INFO - Processing startup event, this is our first event
2021-12-20 01:19:40,351 - octoprint.events - INFO - Adding 1 events to queue that were held back before startup event
2021-12-20 01:19:40,354 - octoprint.filemanager - INFO - Adding backlog items from all storage types to analysis queue...
2021-12-20 01:19:40,416 - octoprint.filemanager - INFO - Added 0 items from storage type "local" to analysis queue
2021-12-20 01:19:40,450 - octoprint.plugins.discovery - INFO - Registered OctoPrint instance on 79f707e4ab0e for SSDP
2021-12-20 01:19:40,456 - octoprint.server - INFO - Listening on http://0.0.0.0:5000
2021-12-20 01:19:40,559 - octoprint.plugins.pluginmanager - ERROR - Could not fetch plugins from repository at https://plugins.octoprint.org/plugins.json: HTTPSConnectionPool(host='plugins.octoprint.org', port=443): Max retries exceeded with url: /plugins.json (Caused by SSLError(SSLError(1, u'[SSL: CERTIFICATE_VERIFY_FAILED] certificate verify failed (_ssl.c:661)'),))
Traceback (most recent call last):
  File "/opt/octoprint/venv/lib/python2.7/site-packages/OctoPrint-1.3.6-py2.7.egg/octoprint/plugins/pluginmanager/__init__.py", line 738, in _fetch_repository_from_url
    r = requests.get(repository_url, timeout=30)
  File "/opt/octoprint/venv/lib/python2.7/site-packages/requests-2.18.4-py2.7.egg/requests/api.py", line 72, in get
    return request('get', url, params=params, **kwargs)
  File "/opt/octoprint/venv/lib/python2.7/site-packages/requests-2.18.4-py2.7.egg/requests/api.py", line 58, in request
    return session.request(method=method, url=url, **kwargs)
  File "/opt/octoprint/venv/lib/python2.7/site-packages/requests-2.18.4-py2.7.egg/requests/sessions.py", line 508, in request
    resp = self.send(prep, **send_kwargs)
  File "/opt/octoprint/venv/lib/python2.7/site-packages/requests-2.18.4-py2.7.egg/requests/sessions.py", line 618, in send
    r = adapter.send(request, **kwargs)
  File "/opt/octoprint/venv/lib/python2.7/site-packages/requests-2.18.4-py2.7.egg/requests/adapters.py", line 506, in send
    raise SSLError(e, request=request)
SSLError: HTTPSConnectionPool(host='plugins.octoprint.org', port=443): Max retries exceeded with url: /plugins.json (Caused by SSLError(SSLError(1, u'[SSL: CERTIFICATE_VERIFY_FAILED] certificate verify failed (_ssl.c:661)'),))
2021-12-20 01:19:40,571 - octoprint.plugins.pluginmanager - ERROR - Could not fetch plugins from repository at https://plugins.octoprint.org/plugins.json: HTTPSConnectionPool(host='plugins.octoprint.org', port=443): Max retries exceeded with url: /plugins.json (Caused by SSLError(SSLError(1, u'[SSL: CERTIFICATE_VERIFY_FAILED] certificate verify failed (_ssl.c:661)'),))
Traceback (most recent call last):
  File "/opt/octoprint/venv/lib/python2.7/site-packages/OctoPrint-1.3.6-py2.7.egg/octoprint/plugins/pluginmanager/__init__.py", line 738, in _fetch_repository_from_url
    r = requests.get(repository_url, timeout=30)
  File "/opt/octoprint/venv/lib/python2.7/site-packages/requests-2.18.4-py2.7.egg/requests/api.py", line 72, in get
    return request('get', url, params=params, **kwargs)
  File "/opt/octoprint/venv/lib/python2.7/site-packages/requests-2.18.4-py2.7.egg/requests/api.py", line 58, in request
    return session.request(method=method, url=url, **kwargs)
  File "/opt/octoprint/venv/lib/python2.7/site-packages/requests-2.18.4-py2.7.egg/requests/sessions.py", line 508, in request
    resp = self.send(prep, **send_kwargs)
  File "/opt/octoprint/venv/lib/python2.7/site-packages/requests-2.18.4-py2.7.egg/requests/sessions.py", line 618, in send
    r = adapter.send(request, **kwargs)
  File "/opt/octoprint/venv/lib/python2.7/site-packages/requests-2.18.4-py2.7.egg/requests/adapters.py", line 506, in send
    raise SSLError(e, request=request)
SSLError: HTTPSConnectionPool(host='plugins.octoprint.org', port=443): Max retries exceeded with url: /plugins.json (Caused by SSLError(SSLError(1, u'[SSL: CERTIFICATE_VERIFY_FAILED] certificate verify failed (_ssl.c:661)'),))
2021-12-20 01:19:40,572 - octoprint.plugins.announcements - ERROR - Could not fetch channel _important from https://octoprint.org/feeds/important.xml: HTTPSConnectionPool(host='octoprint.org', port=443): Max retries exceeded with url: /feeds/important.xml (Caused by SSLError(SSLError(1, u'[SSL: CERTIFICATE_VERIFY_FAILED] certificate verify failed (_ssl.c:661)'),))
Traceback (most recent call last):
  File "/opt/octoprint/venv/lib/python2.7/site-packages/OctoPrint-1.3.6-py2.7.egg/octoprint/plugins/announcements/__init__.py", line 355, in _get_channel_data_from_network
    r = requests.get(url, timeout=30)
  File "/opt/octoprint/venv/lib/python2.7/site-packages/requests-2.18.4-py2.7.egg/requests/api.py", line 72, in get
    return request('get', url, params=params, **kwargs)
  File "/opt/octoprint/venv/lib/python2.7/site-packages/requests-2.18.4-py2.7.egg/requests/api.py", line 58, in request
    return session.request(method=method, url=url, **kwargs)
  File "/opt/octoprint/venv/lib/python2.7/site-packages/requests-2.18.4-py2.7.egg/requests/sessions.py", line 508, in request
    resp = self.send(prep, **send_kwargs)
  File "/opt/octoprint/venv/lib/python2.7/site-packages/requests-2.18.4-py2.7.egg/requests/sessions.py", line 618, in send
    r = adapter.send(request, **kwargs)
  File "/opt/octoprint/venv/lib/python2.7/site-packages/requests-2.18.4-py2.7.egg/requests/adapters.py", line 506, in send
    raise SSLError(e, request=request)
SSLError: HTTPSConnectionPool(host='octoprint.org', port=443): Max retries exceeded with url: /feeds/important.xml (Caused by SSLError(SSLError(1, u'[SSL: CERTIFICATE_VERIFY_FAILED] certificate verify failed (_ssl.c:661)'),))
2021-12-20 01:19:40,575 - octoprint.plugins.announcements - ERROR - Could not fetch channel _important from https://octoprint.org/feeds/important.xml: HTTPSConnectionPool(host='octoprint.org', port=443): Max retries exceeded with url: /feeds/important.xml (Caused by SSLError(SSLError(1, u'[SSL: CERTIFICATE_VERIFY_FAILED] certificate verify failed (_ssl.c:661)'),))
Traceback (most recent call last):
  File "/opt/octoprint/venv/lib/python2.7/site-packages/OctoPrint-1.3.6-py2.7.egg/octoprint/plugins/announcements/__init__.py", line 355, in _get_channel_data_from_network
    r = requests.get(url, timeout=30)
  File "/opt/octoprint/venv/lib/python2.7/site-packages/requests-2.18.4-py2.7.egg/requests/api.py", line 72, in get
    return request('get', url, params=params, **kwargs)
  File "/opt/octoprint/venv/lib/python2.7/site-packages/requests-2.18.4-py2.7.egg/requests/api.py", line 58, in request
    return session.request(method=method, url=url, **kwargs)
  File "/opt/octoprint/venv/lib/python2.7/site-packages/requests-2.18.4-py2.7.egg/requests/sessions.py", line 508, in request
    resp = self.send(prep, **send_kwargs)
  File "/opt/octoprint/venv/lib/python2.7/site-packages/requests-2.18.4-py2.7.egg/requests/sessions.py", line 618, in send
    r = adapter.send(request, **kwargs)
  File "/opt/octoprint/venv/lib/python2.7/site-packages/requests-2.18.4-py2.7.egg/requests/adapters.py", line 506, in send
    raise SSLError(e, request=request)
SSLError: HTTPSConnectionPool(host='octoprint.org', port=443): Max retries exceeded with url: /feeds/important.xml (Caused by SSLError(SSLError(1, u'[SSL: CERTIFICATE_VERIFY_FAILED] certificate verify failed (_ssl.c:661)'),))
2021-12-20 01:19:40,676 - octoprint.plugins.pluginmanager - ERROR - Could not fetch notices from https://plugins.octoprint.org/notices.json: HTTPSConnectionPool(host='plugins.octoprint.org', port=443): Max retries exceeded with url: /notices.json (Caused by SSLError(SSLError(1, u'[SSL: CERTIFICATE_VERIFY_FAILED] certificate verify failed (_ssl.c:661)'),))
Traceback (most recent call last):
  File "/opt/octoprint/venv/lib/python2.7/site-packages/OctoPrint-1.3.6-py2.7.egg/octoprint/plugins/pluginmanager/__init__.py", line 812, in _fetch_notices_from_url
    r = requests.get(notices_url, timeout=30)
  File "/opt/octoprint/venv/lib/python2.7/site-packages/requests-2.18.4-py2.7.egg/requests/api.py", line 72, in get
    return request('get', url, params=params, **kwargs)
  File "/opt/octoprint/venv/lib/python2.7/site-packages/requests-2.18.4-py2.7.egg/requests/api.py", line 58, in request
    return session.request(method=method, url=url, **kwargs)
  File "/opt/octoprint/venv/lib/python2.7/site-packages/requests-2.18.4-py2.7.egg/requests/sessions.py", line 508, in request
    resp = self.send(prep, **send_kwargs)
  File "/opt/octoprint/venv/lib/python2.7/site-packages/requests-2.18.4-py2.7.egg/requests/sessions.py", line 618, in send
    r = adapter.send(request, **kwargs)
  File "/opt/octoprint/venv/lib/python2.7/site-packages/requests-2.18.4-py2.7.egg/requests/adapters.py", line 506, in send
    raise SSLError(e, request=request)
SSLError: HTTPSConnectionPool(host='plugins.octoprint.org', port=443): Max retries exceeded with url: /notices.json (Caused by SSLError(SSLError(1, u'[SSL: CERTIFICATE_VERIFY_FAILED] certificate verify failed (_ssl.c:661)'),))
2021-12-20 01:19:40,682 - octoprint.plugins.announcements - ERROR - Could not fetch channel _releases from https://octoprint.org/feeds/releases.xml: HTTPSConnectionPool(host='octoprint.org', port=443): Max retries exceeded with url: /feeds/releases.xml (Caused by SSLError(SSLError(1, u'[SSL: CERTIFICATE_VERIFY_FAILED] certificate verify failed (_ssl.c:661)'),))
Traceback (most recent call last):
  File "/opt/octoprint/venv/lib/python2.7/site-packages/OctoPrint-1.3.6-py2.7.egg/octoprint/plugins/announcements/__init__.py", line 355, in _get_channel_data_from_network
    r = requests.get(url, timeout=30)
  File "/opt/octoprint/venv/lib/python2.7/site-packages/requests-2.18.4-py2.7.egg/requests/api.py", line 72, in get
    return request('get', url, params=params, **kwargs)
  File "/opt/octoprint/venv/lib/python2.7/site-packages/requests-2.18.4-py2.7.egg/requests/api.py", line 58, in request
    return session.request(method=method, url=url, **kwargs)
  File "/opt/octoprint/venv/lib/python2.7/site-packages/requests-2.18.4-py2.7.egg/requests/sessions.py", line 508, in request
    resp = self.send(prep, **send_kwargs)
  File "/opt/octoprint/venv/lib/python2.7/site-packages/requests-2.18.4-py2.7.egg/requests/sessions.py", line 618, in send
    r = adapter.send(request, **kwargs)
  File "/opt/octoprint/venv/lib/python2.7/site-packages/requests-2.18.4-py2.7.egg/requests/adapters.py", line 506, in send
    raise SSLError(e, request=request)
SSLError: HTTPSConnectionPool(host='octoprint.org', port=443): Max retries exceeded with url: /feeds/releases.xml (Caused by SSLError(SSLError(1, u'[SSL: CERTIFICATE_VERIFY_FAILED] certificate verify failed (_ssl.c:661)'),))
2021-12-20 01:19:40,686 - octoprint.plugins.announcements - ERROR - Could not fetch channel _releases from https://octoprint.org/feeds/releases.xml: HTTPSConnectionPool(host='octoprint.org', port=443): Max retries exceeded with url: /feeds/releases.xml (Caused by SSLError(SSLError(1, u'[SSL: CERTIFICATE_VERIFY_FAILED] certificate verify failed (_ssl.c:661)'),))
Traceback (most recent call last):
  File "/opt/octoprint/venv/lib/python2.7/site-packages/OctoPrint-1.3.6-py2.7.egg/octoprint/plugins/announcements/__init__.py", line 355, in _get_channel_data_from_network
    r = requests.get(url, timeout=30)
  File "/opt/octoprint/venv/lib/python2.7/site-packages/requests-2.18.4-py2.7.egg/requests/api.py", line 72, in get
    return request('get', url, params=params, **kwargs)
  File "/opt/octoprint/venv/lib/python2.7/site-packages/requests-2.18.4-py2.7.egg/requests/api.py", line 58, in request
    return session.request(method=method, url=url, **kwargs)
  File "/opt/octoprint/venv/lib/python2.7/site-packages/requests-2.18.4-py2.7.egg/requests/sessions.py", line 508, in request
    resp = self.send(prep, **send_kwargs)
  File "/opt/octoprint/venv/lib/python2.7/site-packages/requests-2.18.4-py2.7.egg/requests/sessions.py", line 618, in send
    r = adapter.send(request, **kwargs)
  File "/opt/octoprint/venv/lib/python2.7/site-packages/requests-2.18.4-py2.7.egg/requests/adapters.py", line 506, in send
    raise SSLError(e, request=request)
SSLError: HTTPSConnectionPool(host='octoprint.org', port=443): Max retries exceeded with url: /feeds/releases.xml (Caused by SSLError(SSLError(1, u'[SSL: CERTIFICATE_VERIFY_FAILED] certificate verify failed (_ssl.c:661)'),))
2021-12-20 01:19:40,689 - octoprint.plugins.pluginmanager - ERROR - Could not fetch notices from https://plugins.octoprint.org/notices.json: HTTPSConnectionPool(host='plugins.octoprint.org', port=443): Max retries exceeded with url: /notices.json (Caused by SSLError(SSLError(1, u'[SSL: CERTIFICATE_VERIFY_FAILED] certificate verify failed (_ssl.c:661)'),))
Traceback (most recent call last):
  File "/opt/octoprint/venv/lib/python2.7/site-packages/OctoPrint-1.3.6-py2.7.egg/octoprint/plugins/pluginmanager/__init__.py", line 812, in _fetch_notices_from_url
    r = requests.get(notices_url, timeout=30)
  File "/opt/octoprint/venv/lib/python2.7/site-packages/requests-2.18.4-py2.7.egg/requests/api.py", line 72, in get
    return request('get', url, params=params, **kwargs)
  File "/opt/octoprint/venv/lib/python2.7/site-packages/requests-2.18.4-py2.7.egg/requests/api.py", line 58, in request
    return session.request(method=method, url=url, **kwargs)
  File "/opt/octoprint/venv/lib/python2.7/site-packages/requests-2.18.4-py2.7.egg/requests/sessions.py", line 508, in request
    resp = self.send(prep, **send_kwargs)
  File "/opt/octoprint/venv/lib/python2.7/site-packages/requests-2.18.4-py2.7.egg/requests/sessions.py", line 618, in send
    r = adapter.send(request, **kwargs)
  File "/opt/octoprint/venv/lib/python2.7/site-packages/requests-2.18.4-py2.7.egg/requests/adapters.py", line 506, in send
    raise SSLError(e, request=request)
SSLError: HTTPSConnectionPool(host='plugins.octoprint.org', port=443): Max retries exceeded with url: /notices.json (Caused by SSLError(SSLError(1, u'[SSL: CERTIFICATE_VERIFY_FAILED] certificate verify failed (_ssl.c:661)'),))
2021-12-20 01:19:40,795 - octoprint.plugins.announcements - ERROR - Could not fetch channel _blog from https://octoprint.org/feeds/octoblog.xml: HTTPSConnectionPool(host='octoprint.org', port=443): Max retries exceeded with url: /feeds/octoblog.xml (Caused by SSLError(SSLError(1, u'[SSL: CERTIFICATE_VERIFY_FAILED] certificate verify failed (_ssl.c:661)'),))
Traceback (most recent call last):
  File "/opt/octoprint/venv/lib/python2.7/site-packages/OctoPrint-1.3.6-py2.7.egg/octoprint/plugins/announcements/__init__.py", line 355, in _get_channel_data_from_network
    r = requests.get(url, timeout=30)
  File "/opt/octoprint/venv/lib/python2.7/site-packages/requests-2.18.4-py2.7.egg/requests/api.py", line 72, in get
    return request('get', url, params=params, **kwargs)
  File "/opt/octoprint/venv/lib/python2.7/site-packages/requests-2.18.4-py2.7.egg/requests/api.py", line 58, in request
    return session.request(method=method, url=url, **kwargs)
  File "/opt/octoprint/venv/lib/python2.7/site-packages/requests-2.18.4-py2.7.egg/requests/sessions.py", line 508, in request
    resp = self.send(prep, **send_kwargs)
  File "/opt/octoprint/venv/lib/python2.7/site-packages/requests-2.18.4-py2.7.egg/requests/sessions.py", line 618, in send
    r = adapter.send(request, **kwargs)
  File "/opt/octoprint/venv/lib/python2.7/site-packages/requests-2.18.4-py2.7.egg/requests/adapters.py", line 506, in send
    raise SSLError(e, request=request)
SSLError: HTTPSConnectionPool(host='octoprint.org', port=443): Max retries exceeded with url: /feeds/octoblog.xml (Caused by SSLError(SSLError(1, u'[SSL: CERTIFICATE_VERIFY_FAILED] certificate verify failed (_ssl.c:661)'),))
2021-12-20 01:19:40,800 - octoprint.plugins.announcements - ERROR - Could not fetch channel _blog from https://octoprint.org/feeds/octoblog.xml: HTTPSConnectionPool(host='octoprint.org', port=443): Max retries exceeded with url: /feeds/octoblog.xml (Caused by SSLError(SSLError(1, u'[SSL: CERTIFICATE_VERIFY_FAILED] certificate verify failed (_ssl.c:661)'),))
Traceback (most recent call last):
  File "/opt/octoprint/venv/lib/python2.7/site-packages/OctoPrint-1.3.6-py2.7.egg/octoprint/plugins/announcements/__init__.py", line 355, in _get_channel_data_from_network
    r = requests.get(url, timeout=30)
  File "/opt/octoprint/venv/lib/python2.7/site-packages/requests-2.18.4-py2.7.egg/requests/api.py", line 72, in get
    return request('get', url, params=params, **kwargs)
  File "/opt/octoprint/venv/lib/python2.7/site-packages/requests-2.18.4-py2.7.egg/requests/api.py", line 58, in request
    return session.request(method=method, url=url, **kwargs)
  File "/opt/octoprint/venv/lib/python2.7/site-packages/requests-2.18.4-py2.7.egg/requests/sessions.py", line 508, in request
    resp = self.send(prep, **send_kwargs)
  File "/opt/octoprint/venv/lib/python2.7/site-packages/requests-2.18.4-py2.7.egg/requests/sessions.py", line 618, in send
    r = adapter.send(request, **kwargs)
  File "/opt/octoprint/venv/lib/python2.7/site-packages/requests-2.18.4-py2.7.egg/requests/adapters.py", line 506, in send
    raise SSLError(e, request=request)
SSLError: HTTPSConnectionPool(host='octoprint.org', port=443): Max retries exceeded with url: /feeds/octoblog.xml (Caused by SSLError(SSLError(1, u'[SSL: CERTIFICATE_VERIFY_FAILED] certificate verify failed (_ssl.c:661)'),))
2021-12-20 01:19:40,918 - octoprint.plugins.announcements - ERROR - Could not fetch channel _plugins from https://plugins.octoprint.org/feed.xml: HTTPSConnectionPool(host='plugins.octoprint.org', port=443): Max retries exceeded with url: /feed.xml (Caused by SSLError(SSLError(1, u'[SSL: CERTIFICATE_VERIFY_FAILED] certificate verify failed (_ssl.c:661)'),))
Traceback (most recent call last):
  File "/opt/octoprint/venv/lib/python2.7/site-packages/OctoPrint-1.3.6-py2.7.egg/octoprint/plugins/announcements/__init__.py", line 355, in _get_channel_data_from_network
    r = requests.get(url, timeout=30)
  File "/opt/octoprint/venv/lib/python2.7/site-packages/requests-2.18.4-py2.7.egg/requests/api.py", line 72, in get
    return request('get', url, params=params, **kwargs)
  File "/opt/octoprint/venv/lib/python2.7/site-packages/requests-2.18.4-py2.7.egg/requests/api.py", line 58, in request
    return session.request(method=method, url=url, **kwargs)
  File "/opt/octoprint/venv/lib/python2.7/site-packages/requests-2.18.4-py2.7.egg/requests/sessions.py", line 508, in request
    resp = self.send(prep, **send_kwargs)
  File "/opt/octoprint/venv/lib/python2.7/site-packages/requests-2.18.4-py2.7.egg/requests/sessions.py", line 618, in send
    r = adapter.send(request, **kwargs)
  File "/opt/octoprint/venv/lib/python2.7/site-packages/requests-2.18.4-py2.7.egg/requests/adapters.py", line 506, in send
    raise SSLError(e, request=request)
SSLError: HTTPSConnectionPool(host='plugins.octoprint.org', port=443): Max retries exceeded with url: /feed.xml (Caused by SSLError(SSLError(1, u'[SSL: CERTIFICATE_VERIFY_FAILED] certificate verify failed (_ssl.c:661)'),))
2021-12-20 01:19:40,923 - octoprint.plugins.announcements - ERROR - Could not fetch channel _plugins from https://plugins.octoprint.org/feed.xml: HTTPSConnectionPool(host='plugins.octoprint.org', port=443): Max retries exceeded with url: /feed.xml (Caused by SSLError(SSLError(1, u'[SSL: CERTIFICATE_VERIFY_FAILED] certificate verify failed (_ssl.c:661)'),))
Traceback (most recent call last):
  File "/opt/octoprint/venv/lib/python2.7/site-packages/OctoPrint-1.3.6-py2.7.egg/octoprint/plugins/announcements/__init__.py", line 355, in _get_channel_data_from_network
    r = requests.get(url, timeout=30)
  File "/opt/octoprint/venv/lib/python2.7/site-packages/requests-2.18.4-py2.7.egg/requests/api.py", line 72, in get
    return request('get', url, params=params, **kwargs)
  File "/opt/octoprint/venv/lib/python2.7/site-packages/requests-2.18.4-py2.7.egg/requests/api.py", line 58, in request
    return session.request(method=method, url=url, **kwargs)
  File "/opt/octoprint/venv/lib/python2.7/site-packages/requests-2.18.4-py2.7.egg/requests/sessions.py", line 508, in request
    resp = self.send(prep, **send_kwargs)
  File "/opt/octoprint/venv/lib/python2.7/site-packages/requests-2.18.4-py2.7.egg/requests/sessions.py", line 618, in send
    r = adapter.send(request, **kwargs)
  File "/opt/octoprint/venv/lib/python2.7/site-packages/requests-2.18.4-py2.7.egg/requests/adapters.py", line 506, in send
    raise SSLError(e, request=request)
SSLError: HTTPSConnectionPool(host='plugins.octoprint.org', port=443): Max retries exceeded with url: /feed.xml (Caused by SSLError(SSLError(1, u'[SSL: CERTIFICATE_VERIFY_FAILED] certificate verify failed (_ssl.c:661)'),))
2021-12-20 01:19:41,037 - octoprint.plugins.announcements - ERROR - Could not fetch channel _octopi from https://octoprint.org/feeds/octopi.xml: HTTPSConnectionPool(host='octoprint.org', port=443): Max retries exceeded with url: /feeds/octopi.xml (Caused by SSLError(SSLError(1, u'[SSL: CERTIFICATE_VERIFY_FAILED] certificate verify failed (_ssl.c:661)'),))
Traceback (most recent call last):
  File "/opt/octoprint/venv/lib/python2.7/site-packages/OctoPrint-1.3.6-py2.7.egg/octoprint/plugins/announcements/__init__.py", line 355, in _get_channel_data_from_network
    r = requests.get(url, timeout=30)
  File "/opt/octoprint/venv/lib/python2.7/site-packages/requests-2.18.4-py2.7.egg/requests/api.py", line 72, in get
    return request('get', url, params=params, **kwargs)
  File "/opt/octoprint/venv/lib/python2.7/site-packages/requests-2.18.4-py2.7.egg/requests/api.py", line 58, in request
    return session.request(method=method, url=url, **kwargs)
  File "/opt/octoprint/venv/lib/python2.7/site-packages/requests-2.18.4-py2.7.egg/requests/sessions.py", line 508, in request
    resp = self.send(prep, **send_kwargs)
  File "/opt/octoprint/venv/lib/python2.7/site-packages/requests-2.18.4-py2.7.egg/requests/sessions.py", line 618, in send
    r = adapter.send(request, **kwargs)
  File "/opt/octoprint/venv/lib/python2.7/site-packages/requests-2.18.4-py2.7.egg/requests/adapters.py", line 506, in send
    raise SSLError(e, request=request)
SSLError: HTTPSConnectionPool(host='octoprint.org', port=443): Max retries exceeded with url: /feeds/octopi.xml (Caused by SSLError(SSLError(1, u'[SSL: CERTIFICATE_VERIFY_FAILED] certificate verify failed (_ssl.c:661)'),))
2021-12-20 01:19:41,042 - octoprint.plugins.announcements - ERROR - Could not fetch channel _octopi from https://octoprint.org/feeds/octopi.xml: HTTPSConnectionPool(host='octoprint.org', port=443): Max retries exceeded with url: /feeds/octopi.xml (Caused by SSLError(SSLError(1, u'[SSL: CERTIFICATE_VERIFY_FAILED] certificate verify failed (_ssl.c:661)'),))
Traceback (most recent call last):
  File "/opt/octoprint/venv/lib/python2.7/site-packages/OctoPrint-1.3.6-py2.7.egg/octoprint/plugins/announcements/__init__.py", line 355, in _get_channel_data_from_network
    r = requests.get(url, timeout=30)
  File "/opt/octoprint/venv/lib/python2.7/site-packages/requests-2.18.4-py2.7.egg/requests/api.py", line 72, in get
    return request('get', url, params=params, **kwargs)
  File "/opt/octoprint/venv/lib/python2.7/site-packages/requests-2.18.4-py2.7.egg/requests/api.py", line 58, in request
    return session.request(method=method, url=url, **kwargs)
  File "/opt/octoprint/venv/lib/python2.7/site-packages/requests-2.18.4-py2.7.egg/requests/sessions.py", line 508, in request
    resp = self.send(prep, **send_kwargs)
  File "/opt/octoprint/venv/lib/python2.7/site-packages/requests-2.18.4-py2.7.egg/requests/sessions.py", line 618, in send
    r = adapter.send(request, **kwargs)
  File "/opt/octoprint/venv/lib/python2.7/site-packages/requests-2.18.4-py2.7.egg/requests/adapters.py", line 506, in send
    raise SSLError(e, request=request)
SSLError: HTTPSConnectionPool(host='octoprint.org', port=443): Max retries exceeded with url: /feeds/octopi.xml (Caused by SSLError(SSLError(1, u'[SSL: CERTIFICATE_VERIFY_FAILED] certificate verify failed (_ssl.c:661)'),))
2021-12-20 01:19:41,570 - octoprint.util.pip - INFO - Using "/opt/octoprint/venv/bin/python -m pip" as command to invoke pip
2021-12-20 01:19:42,990 - octoprint.util.pip - INFO - pip installs to /opt/octoprint/venv/lib/python2.7/site-packages/, --user flag needed => no, virtual env => yes
2021-12-20 01:19:43,008 - octoprint.plugins.softwareupdate - INFO - Saved version cache to disk
2021-12-20 01:26:22,345 - octoprint.server - INFO - Shutting down...
2021-12-20 01:26:23,204 - octoprint.events - INFO - Processing shutdown event, this will be our last event
2021-12-20 01:26:23,208 - octoprint.events - INFO - Event loop shut down
2021-12-20 01:26:23,210 - octoprint.server - INFO - Goodbye!
2021-12-20 01:26:24,920 - octoprint.startup - INFO - ******************************************************************************
2021-12-20 01:26:24,921 - octoprint.startup - INFO - Starting OctoPrint 1.3.6
2021-12-20 01:26:24,922 - octoprint.startup - INFO - ******************************************************************************
2021-12-20 01:26:24,943 - octoprint.plugin.core - INFO - Loading plugins from /opt/octoprint/venv/lib/python2.7/site-packages/OctoPrint-1.3.6-py2.7.egg/octoprint/plugins, /home/octoprint/.octoprint/plugins and installed plugin packages...
2021-12-20 01:26:24,952 - octoprint.util.connectivity_checker - INFO - Connectivity changed from offline to online
2021-12-20 01:26:25,370 - octoprint.plugin.core - WARNING - Plugin "OctoPi Support Plugin" did not pass check
2021-12-20 01:26:25,387 - octoprint.plugins.discovery - INFO - pybonjour is not installed, Zeroconf Discovery won't be available
2021-12-20 01:26:25,390 - octoprint.plugin.core - INFO - Found 7 plugin(s) providing 7 mixin implementations, 4 hook handlers
2021-12-20 01:26:25,425 - octoprint.server - INFO - Intermediary server started
2021-12-20 01:26:25,426 - octoprint.plugin.core - INFO - Loading plugins from /opt/octoprint/venv/lib/python2.7/site-packages/OctoPrint-1.3.6-py2.7.egg/octoprint/plugins, /home/octoprint/.octoprint/plugins and installed plugin packages...
2021-12-20 01:26:25,427 - octoprint.plugin.core - WARNING - Plugin "OctoPi Support Plugin" did not pass check
2021-12-20 01:26:25,443 - octoprint.plugin.core - INFO - Found 7 plugin(s) providing 7 mixin implementations, 4 hook handlers
2021-12-20 01:26:25,460 - octoprint.filemanager.storage - INFO - Initializing the file metadata for /home/octoprint/.octoprint/uploads...
2021-12-20 01:26:25,614 - octoprint.filemanager.storage - INFO - ... file metadata for /home/octoprint/.octoprint/uploads initialized successfully.
2021-12-20 01:26:25,629 - octoprint.plugins.softwareupdate - INFO - Loaded version cache from disk
2021-12-20 01:26:26,031 - octoprint.util.pip - INFO - Using "/opt/octoprint/venv/bin/python -m pip" as command to invoke pip
2021-12-20 01:26:26,421 - octoprint.util.pip - INFO - Version of pip is 9.0.1
2021-12-20 01:26:26,423 - octoprint.plugin.core - INFO - Initialized 7 plugin implementation(s)
2021-12-20 01:26:26,426 - octoprint.plugin.core - INFO - 7 plugin(s) registered with the system:
|  Announcement Plugin (bundled) = /opt/octoprint/venv/lib/python2.7/site-packages/OctoPrint-1.3.6-py2.7.egg/octoprint/plugins/announcements
|  Core Wizard (bundled) = /opt/octoprint/venv/lib/python2.7/site-packages/OctoPrint-1.3.6-py2.7.egg/octoprint/plugins/corewizard
|  CuraEngine (<= 15.04) (bundled) = /opt/octoprint/venv/lib/python2.7/site-packages/OctoPrint-1.3.6-py2.7.egg/octoprint/plugins/cura
|  Discovery (bundled) = /opt/octoprint/venv/lib/python2.7/site-packages/OctoPrint-1.3.6-py2.7.egg/octoprint/plugins/discovery
|  Plugin Manager (bundled) = /opt/octoprint/venv/lib/python2.7/site-packages/OctoPrint-1.3.6-py2.7.egg/octoprint/plugins/pluginmanager
|  Software Update (bundled) = /opt/octoprint/venv/lib/python2.7/site-packages/OctoPrint-1.3.6-py2.7.egg/octoprint/plugins/softwareupdate
|  Virtual Printer (bundled) = /opt/octoprint/venv/lib/python2.7/site-packages/OctoPrint-1.3.6-py2.7.egg/octoprint/plugins/virtual_printer
2021-12-20 01:26:26,743 - octoprint.environment - INFO - Detected environment is Python 2.7.14 under Linux (linux2). Details:
|  hardware:
|    cores: 4
|    freq: unknown
|    ram: 2082197504
|  os:
|    id: linux
|    platform: linux2
|  python:
|    pip: 9.0.1
|    version: 2.7.14
|    virtualenv: /opt/octoprint/venv
2021-12-20 01:26:26,753 - octoprint.server - INFO - Reset webasset folder /home/octoprint/.octoprint/generated/webassets...
2021-12-20 01:26:26,760 - octoprint.server - INFO - Reset webasset folder /home/octoprint/.octoprint/generated/.webassets-cache...
2021-12-20 01:26:26,811 - octoprint.server - INFO - Shutting down intermediary server...
2021-12-20 01:26:26,927 - octoprint.server - INFO - Intermediary server shut down
2021-12-20 01:26:26,929 - octoprint.events - INFO - Processing startup event, this is our first event
2021-12-20 01:26:26,931 - octoprint.events - INFO - Adding 1 events to queue that were held back before startup event
2021-12-20 01:26:26,934 - octoprint.filemanager - INFO - Adding backlog items from all storage types to analysis queue...
2021-12-20 01:26:26,997 - octoprint.filemanager - INFO - Added 0 items from storage type "local" to analysis queue
2021-12-20 01:26:27,019 - octoprint.plugins.discovery - INFO - Registered OctoPrint instance on a32db404ef96 for SSDP
2021-12-20 01:26:27,023 - octoprint.server - INFO - Listening on http://0.0.0.0:5000
2021-12-20 01:26:27,111 - octoprint.plugins.pluginmanager - ERROR - Could not fetch plugins from repository at https://plugins.octoprint.org/plugins.json: HTTPSConnectionPool(host='plugins.octoprint.org', port=443): Max retries exceeded with url: /plugins.json (Caused by SSLError(SSLError(1, u'[SSL: CERTIFICATE_VERIFY_FAILED] certificate verify failed (_ssl.c:661)'),))
Traceback (most recent call last):
  File "/opt/octoprint/venv/lib/python2.7/site-packages/OctoPrint-1.3.6-py2.7.egg/octoprint/plugins/pluginmanager/__init__.py", line 738, in _fetch_repository_from_url
    r = requests.get(repository_url, timeout=30)
  File "/opt/octoprint/venv/lib/python2.7/site-packages/requests-2.18.4-py2.7.egg/requests/api.py", line 72, in get
    return request('get', url, params=params, **kwargs)
  File "/opt/octoprint/venv/lib/python2.7/site-packages/requests-2.18.4-py2.7.egg/requests/api.py", line 58, in request
    return session.request(method=method, url=url, **kwargs)
  File "/opt/octoprint/venv/lib/python2.7/site-packages/requests-2.18.4-py2.7.egg/requests/sessions.py", line 508, in request
    resp = self.send(prep, **send_kwargs)
  File "/opt/octoprint/venv/lib/python2.7/site-packages/requests-2.18.4-py2.7.egg/requests/sessions.py", line 618, in send
    r = adapter.send(request, **kwargs)
  File "/opt/octoprint/venv/lib/python2.7/site-packages/requests-2.18.4-py2.7.egg/requests/adapters.py", line 506, in send
    raise SSLError(e, request=request)
SSLError: HTTPSConnectionPool(host='plugins.octoprint.org', port=443): Max retries exceeded with url: /plugins.json (Caused by SSLError(SSLError(1, u'[SSL: CERTIFICATE_VERIFY_FAILED] certificate verify failed (_ssl.c:661)'),))
2021-12-20 01:26:27,193 - octoprint.plugins.announcements - ERROR - Could not fetch channel _important from https://octoprint.org/feeds/important.xml: HTTPSConnectionPool(host='octoprint.org', port=443): Max retries exceeded with url: /feeds/important.xml (Caused by SSLError(SSLError(1, u'[SSL: CERTIFICATE_VERIFY_FAILED] certificate verify failed (_ssl.c:661)'),))
Traceback (most recent call last):
  File "/opt/octoprint/venv/lib/python2.7/site-packages/OctoPrint-1.3.6-py2.7.egg/octoprint/plugins/announcements/__init__.py", line 355, in _get_channel_data_from_network
    r = requests.get(url, timeout=30)
  File "/opt/octoprint/venv/lib/python2.7/site-packages/requests-2.18.4-py2.7.egg/requests/api.py", line 72, in get
    return request('get', url, params=params, **kwargs)
  File "/opt/octoprint/venv/lib/python2.7/site-packages/requests-2.18.4-py2.7.egg/requests/api.py", line 58, in request
    return session.request(method=method, url=url, **kwargs)
  File "/opt/octoprint/venv/lib/python2.7/site-packages/requests-2.18.4-py2.7.egg/requests/sessions.py", line 508, in request
    resp = self.send(prep, **send_kwargs)
  File "/opt/octoprint/venv/lib/python2.7/site-packages/requests-2.18.4-py2.7.egg/requests/sessions.py", line 618, in send
    r = adapter.send(request, **kwargs)
  File "/opt/octoprint/venv/lib/python2.7/site-packages/requests-2.18.4-py2.7.egg/requests/adapters.py", line 506, in send
    raise SSLError(e, request=request)
SSLError: HTTPSConnectionPool(host='octoprint.org', port=443): Max retries exceeded with url: /feeds/important.xml (Caused by SSLError(SSLError(1, u'[SSL: CERTIFICATE_VERIFY_FAILED] certificate verify failed (_ssl.c:661)'),))
2021-12-20 01:26:27,198 - octoprint.plugins.pluginmanager - ERROR - Could not fetch plugins from repository at https://plugins.octoprint.org/plugins.json: HTTPSConnectionPool(host='plugins.octoprint.org', port=443): Max retries exceeded with url: /plugins.json (Caused by SSLError(SSLError(1, u'[SSL: CERTIFICATE_VERIFY_FAILED] certificate verify failed (_ssl.c:661)'),))
Traceback (most recent call last):
  File "/opt/octoprint/venv/lib/python2.7/site-packages/OctoPrint-1.3.6-py2.7.egg/octoprint/plugins/pluginmanager/__init__.py", line 738, in _fetch_repository_from_url
    r = requests.get(repository_url, timeout=30)
  File "/opt/octoprint/venv/lib/python2.7/site-packages/requests-2.18.4-py2.7.egg/requests/api.py", line 72, in get
    return request('get', url, params=params, **kwargs)
  File "/opt/octoprint/venv/lib/python2.7/site-packages/requests-2.18.4-py2.7.egg/requests/api.py", line 58, in request
    return session.request(method=method, url=url, **kwargs)
  File "/opt/octoprint/venv/lib/python2.7/site-packages/requests-2.18.4-py2.7.egg/requests/sessions.py", line 508, in request
    resp = self.send(prep, **send_kwargs)
  File "/opt/octoprint/venv/lib/python2.7/site-packages/requests-2.18.4-py2.7.egg/requests/sessions.py", line 618, in send
    r = adapter.send(request, **kwargs)
  File "/opt/octoprint/venv/lib/python2.7/site-packages/requests-2.18.4-py2.7.egg/requests/adapters.py", line 506, in send
    raise SSLError(e, request=request)
SSLError: HTTPSConnectionPool(host='plugins.octoprint.org', port=443): Max retries exceeded with url: /plugins.json (Caused by SSLError(SSLError(1, u'[SSL: CERTIFICATE_VERIFY_FAILED] certificate verify failed (_ssl.c:661)'),))
2021-12-20 01:26:27,199 - octoprint.plugins.announcements - ERROR - Could not fetch channel _important from https://octoprint.org/feeds/important.xml: HTTPSConnectionPool(host='octoprint.org', port=443): Max retries exceeded with url: /feeds/important.xml (Caused by SSLError(SSLError(1, u'[SSL: CERTIFICATE_VERIFY_FAILED] certificate verify failed (_ssl.c:661)'),))
Traceback (most recent call last):
  File "/opt/octoprint/venv/lib/python2.7/site-packages/OctoPrint-1.3.6-py2.7.egg/octoprint/plugins/announcements/__init__.py", line 355, in _get_channel_data_from_network
    r = requests.get(url, timeout=30)
  File "/opt/octoprint/venv/lib/python2.7/site-packages/requests-2.18.4-py2.7.egg/requests/api.py", line 72, in get
    return request('get', url, params=params, **kwargs)
  File "/opt/octoprint/venv/lib/python2.7/site-packages/requests-2.18.4-py2.7.egg/requests/api.py", line 58, in request
    return session.request(method=method, url=url, **kwargs)
  File "/opt/octoprint/venv/lib/python2.7/site-packages/requests-2.18.4-py2.7.egg/requests/sessions.py", line 508, in request
    resp = self.send(prep, **send_kwargs)
  File "/opt/octoprint/venv/lib/python2.7/site-packages/requests-2.18.4-py2.7.egg/requests/sessions.py", line 618, in send
    r = adapter.send(request, **kwargs)
  File "/opt/octoprint/venv/lib/python2.7/site-packages/requests-2.18.4-py2.7.egg/requests/adapters.py", line 506, in send
    raise SSLError(e, request=request)
SSLError: HTTPSConnectionPool(host='octoprint.org', port=443): Max retries exceeded with url: /feeds/important.xml (Caused by SSLError(SSLError(1, u'[SSL: CERTIFICATE_VERIFY_FAILED] certificate verify failed (_ssl.c:661)'),))
2021-12-20 01:26:27,229 - octoprint.plugins.pluginmanager - ERROR - Could not fetch notices from https://plugins.octoprint.org/notices.json: HTTPSConnectionPool(host='plugins.octoprint.org', port=443): Max retries exceeded with url: /notices.json (Caused by SSLError(SSLError(1, u'[SSL: CERTIFICATE_VERIFY_FAILED] certificate verify failed (_ssl.c:661)'),))
Traceback (most recent call last):
  File "/opt/octoprint/venv/lib/python2.7/site-packages/OctoPrint-1.3.6-py2.7.egg/octoprint/plugins/pluginmanager/__init__.py", line 812, in _fetch_notices_from_url
    r = requests.get(notices_url, timeout=30)
  File "/opt/octoprint/venv/lib/python2.7/site-packages/requests-2.18.4-py2.7.egg/requests/api.py", line 72, in get
    return request('get', url, params=params, **kwargs)
  File "/opt/octoprint/venv/lib/python2.7/site-packages/requests-2.18.4-py2.7.egg/requests/api.py", line 58, in request
    return session.request(method=method, url=url, **kwargs)
  File "/opt/octoprint/venv/lib/python2.7/site-packages/requests-2.18.4-py2.7.egg/requests/sessions.py", line 508, in request
    resp = self.send(prep, **send_kwargs)
  File "/opt/octoprint/venv/lib/python2.7/site-packages/requests-2.18.4-py2.7.egg/requests/sessions.py", line 618, in send
    r = adapter.send(request, **kwargs)
  File "/opt/octoprint/venv/lib/python2.7/site-packages/requests-2.18.4-py2.7.egg/requests/adapters.py", line 506, in send
    raise SSLError(e, request=request)
SSLError: HTTPSConnectionPool(host='plugins.octoprint.org', port=443): Max retries exceeded with url: /notices.json (Caused by SSLError(SSLError(1, u'[SSL: CERTIFICATE_VERIFY_FAILED] certificate verify failed (_ssl.c:661)'),))
2021-12-20 01:26:27,314 - octoprint.plugins.announcements - ERROR - Could not fetch channel _releases from https://octoprint.org/feeds/releases.xml: HTTPSConnectionPool(host='octoprint.org', port=443): Max retries exceeded with url: /feeds/releases.xml (Caused by SSLError(SSLError(1, u'[SSL: CERTIFICATE_VERIFY_FAILED] certificate verify failed (_ssl.c:661)'),))
Traceback (most recent call last):
  File "/opt/octoprint/venv/lib/python2.7/site-packages/OctoPrint-1.3.6-py2.7.egg/octoprint/plugins/announcements/__init__.py", line 355, in _get_channel_data_from_network
    r = requests.get(url, timeout=30)
  File "/opt/octoprint/venv/lib/python2.7/site-packages/requests-2.18.4-py2.7.egg/requests/api.py", line 72, in get
    return request('get', url, params=params, **kwargs)
  File "/opt/octoprint/venv/lib/python2.7/site-packages/requests-2.18.4-py2.7.egg/requests/api.py", line 58, in request
    return session.request(method=method, url=url, **kwargs)
  File "/opt/octoprint/venv/lib/python2.7/site-packages/requests-2.18.4-py2.7.egg/requests/sessions.py", line 508, in request
    resp = self.send(prep, **send_kwargs)
  File "/opt/octoprint/venv/lib/python2.7/site-packages/requests-2.18.4-py2.7.egg/requests/sessions.py", line 618, in send
    r = adapter.send(request, **kwargs)
  File "/opt/octoprint/venv/lib/python2.7/site-packages/requests-2.18.4-py2.7.egg/requests/adapters.py", line 506, in send
    raise SSLError(e, request=request)
SSLError: HTTPSConnectionPool(host='octoprint.org', port=443): Max retries exceeded with url: /feeds/releases.xml (Caused by SSLError(SSLError(1, u'[SSL: CERTIFICATE_VERIFY_FAILED] certificate verify failed (_ssl.c:661)'),))
2021-12-20 01:26:27,319 - octoprint.plugins.pluginmanager - ERROR - Could not fetch notices from https://plugins.octoprint.org/notices.json: HTTPSConnectionPool(host='plugins.octoprint.org', port=443): Max retries exceeded with url: /notices.json (Caused by SSLError(SSLError(1, u'[SSL: CERTIFICATE_VERIFY_FAILED] certificate verify failed (_ssl.c:661)'),))
Traceback (most recent call last):
  File "/opt/octoprint/venv/lib/python2.7/site-packages/OctoPrint-1.3.6-py2.7.egg/octoprint/plugins/pluginmanager/__init__.py", line 812, in _fetch_notices_from_url
    r = requests.get(notices_url, timeout=30)
  File "/opt/octoprint/venv/lib/python2.7/site-packages/requests-2.18.4-py2.7.egg/requests/api.py", line 72, in get
    return request('get', url, params=params, **kwargs)
  File "/opt/octoprint/venv/lib/python2.7/site-packages/requests-2.18.4-py2.7.egg/requests/api.py", line 58, in request
    return session.request(method=method, url=url, **kwargs)
  File "/opt/octoprint/venv/lib/python2.7/site-packages/requests-2.18.4-py2.7.egg/requests/sessions.py", line 508, in request
    resp = self.send(prep, **send_kwargs)
  File "/opt/octoprint/venv/lib/python2.7/site-packages/requests-2.18.4-py2.7.egg/requests/sessions.py", line 618, in send
    r = adapter.send(request, **kwargs)
  File "/opt/octoprint/venv/lib/python2.7/site-packages/requests-2.18.4-py2.7.egg/requests/adapters.py", line 506, in send
    raise SSLError(e, request=request)
SSLError: HTTPSConnectionPool(host='plugins.octoprint.org', port=443): Max retries exceeded with url: /notices.json (Caused by SSLError(SSLError(1, u'[SSL: CERTIFICATE_VERIFY_FAILED] certificate verify failed (_ssl.c:661)'),))
2021-12-20 01:26:27,319 - octoprint.plugins.announcements - ERROR - Could not fetch channel _releases from https://octoprint.org/feeds/releases.xml: HTTPSConnectionPool(host='octoprint.org', port=443): Max retries exceeded with url: /feeds/releases.xml (Caused by SSLError(SSLError(1, u'[SSL: CERTIFICATE_VERIFY_FAILED] certificate verify failed (_ssl.c:661)'),))
Traceback (most recent call last):
  File "/opt/octoprint/venv/lib/python2.7/site-packages/OctoPrint-1.3.6-py2.7.egg/octoprint/plugins/announcements/__init__.py", line 355, in _get_channel_data_from_network
    r = requests.get(url, timeout=30)
  File "/opt/octoprint/venv/lib/python2.7/site-packages/requests-2.18.4-py2.7.egg/requests/api.py", line 72, in get
    return request('get', url, params=params, **kwargs)
  File "/opt/octoprint/venv/lib/python2.7/site-packages/requests-2.18.4-py2.7.egg/requests/api.py", line 58, in request
    return session.request(method=method, url=url, **kwargs)
  File "/opt/octoprint/venv/lib/python2.7/site-packages/requests-2.18.4-py2.7.egg/requests/sessions.py", line 508, in request
    resp = self.send(prep, **send_kwargs)
  File "/opt/octoprint/venv/lib/python2.7/site-packages/requests-2.18.4-py2.7.egg/requests/sessions.py", line 618, in send
    r = adapter.send(request, **kwargs)
  File "/opt/octoprint/venv/lib/python2.7/site-packages/requests-2.18.4-py2.7.egg/requests/adapters.py", line 506, in send
    raise SSLError(e, request=request)
SSLError: HTTPSConnectionPool(host='octoprint.org', port=443): Max retries exceeded with url: /feeds/releases.xml (Caused by SSLError(SSLError(1, u'[SSL: CERTIFICATE_VERIFY_FAILED] certificate verify failed (_ssl.c:661)'),))
2021-12-20 01:26:27,433 - octoprint.plugins.announcements - ERROR - Could not fetch channel _blog from https://octoprint.org/feeds/octoblog.xml: HTTPSConnectionPool(host='octoprint.org', port=443): Max retries exceeded with url: /feeds/octoblog.xml (Caused by SSLError(SSLError(1, u'[SSL: CERTIFICATE_VERIFY_FAILED] certificate verify failed (_ssl.c:661)'),))
Traceback (most recent call last):
  File "/opt/octoprint/venv/lib/python2.7/site-packages/OctoPrint-1.3.6-py2.7.egg/octoprint/plugins/announcements/__init__.py", line 355, in _get_channel_data_from_network
    r = requests.get(url, timeout=30)
  File "/opt/octoprint/venv/lib/python2.7/site-packages/requests-2.18.4-py2.7.egg/requests/api.py", line 72, in get
    return request('get', url, params=params, **kwargs)
  File "/opt/octoprint/venv/lib/python2.7/site-packages/requests-2.18.4-py2.7.egg/requests/api.py", line 58, in request
    return session.request(method=method, url=url, **kwargs)
  File "/opt/octoprint/venv/lib/python2.7/site-packages/requests-2.18.4-py2.7.egg/requests/sessions.py", line 508, in request
    resp = self.send(prep, **send_kwargs)
  File "/opt/octoprint/venv/lib/python2.7/site-packages/requests-2.18.4-py2.7.egg/requests/sessions.py", line 618, in send
    r = adapter.send(request, **kwargs)
  File "/opt/octoprint/venv/lib/python2.7/site-packages/requests-2.18.4-py2.7.egg/requests/adapters.py", line 506, in send
    raise SSLError(e, request=request)
SSLError: HTTPSConnectionPool(host='octoprint.org', port=443): Max retries exceeded with url: /feeds/octoblog.xml (Caused by SSLError(SSLError(1, u'[SSL: CERTIFICATE_VERIFY_FAILED] certificate verify failed (_ssl.c:661)'),))
2021-12-20 01:26:27,437 - octoprint.plugins.announcements - ERROR - Could not fetch channel _blog from https://octoprint.org/feeds/octoblog.xml: HTTPSConnectionPool(host='octoprint.org', port=443): Max retries exceeded with url: /feeds/octoblog.xml (Caused by SSLError(SSLError(1, u'[SSL: CERTIFICATE_VERIFY_FAILED] certificate verify failed (_ssl.c:661)'),))
Traceback (most recent call last):
  File "/opt/octoprint/venv/lib/python2.7/site-packages/OctoPrint-1.3.6-py2.7.egg/octoprint/plugins/announcements/__init__.py", line 355, in _get_channel_data_from_network
    r = requests.get(url, timeout=30)
  File "/opt/octoprint/venv/lib/python2.7/site-packages/requests-2.18.4-py2.7.egg/requests/api.py", line 72, in get
    return request('get', url, params=params, **kwargs)
  File "/opt/octoprint/venv/lib/python2.7/site-packages/requests-2.18.4-py2.7.egg/requests/api.py", line 58, in request
    return session.request(method=method, url=url, **kwargs)
  File "/opt/octoprint/venv/lib/python2.7/site-packages/requests-2.18.4-py2.7.egg/requests/sessions.py", line 508, in request
    resp = self.send(prep, **send_kwargs)
  File "/opt/octoprint/venv/lib/python2.7/site-packages/requests-2.18.4-py2.7.egg/requests/sessions.py", line 618, in send
    r = adapter.send(request, **kwargs)
  File "/opt/octoprint/venv/lib/python2.7/site-packages/requests-2.18.4-py2.7.egg/requests/adapters.py", line 506, in send
    raise SSLError(e, request=request)
SSLError: HTTPSConnectionPool(host='octoprint.org', port=443): Max retries exceeded with url: /feeds/octoblog.xml (Caused by SSLError(SSLError(1, u'[SSL: CERTIFICATE_VERIFY_FAILED] certificate verify failed (_ssl.c:661)'),))
2021-12-20 01:26:27,555 - octoprint.plugins.announcements - ERROR - Could not fetch channel _plugins from https://plugins.octoprint.org/feed.xml: HTTPSConnectionPool(host='plugins.octoprint.org', port=443): Max retries exceeded with url: /feed.xml (Caused by SSLError(SSLError(1, u'[SSL: CERTIFICATE_VERIFY_FAILED] certificate verify failed (_ssl.c:661)'),))
Traceback (most recent call last):
  File "/opt/octoprint/venv/lib/python2.7/site-packages/OctoPrint-1.3.6-py2.7.egg/octoprint/plugins/announcements/__init__.py", line 355, in _get_channel_data_from_network
    r = requests.get(url, timeout=30)
  File "/opt/octoprint/venv/lib/python2.7/site-packages/requests-2.18.4-py2.7.egg/requests/api.py", line 72, in get
    return request('get', url, params=params, **kwargs)
  File "/opt/octoprint/venv/lib/python2.7/site-packages/requests-2.18.4-py2.7.egg/requests/api.py", line 58, in request
    return session.request(method=method, url=url, **kwargs)
  File "/opt/octoprint/venv/lib/python2.7/site-packages/requests-2.18.4-py2.7.egg/requests/sessions.py", line 508, in request
    resp = self.send(prep, **send_kwargs)
  File "/opt/octoprint/venv/lib/python2.7/site-packages/requests-2.18.4-py2.7.egg/requests/sessions.py", line 618, in send
    r = adapter.send(request, **kwargs)
  File "/opt/octoprint/venv/lib/python2.7/site-packages/requests-2.18.4-py2.7.egg/requests/adapters.py", line 506, in send
    raise SSLError(e, request=request)
SSLError: HTTPSConnectionPool(host='plugins.octoprint.org', port=443): Max retries exceeded with url: /feed.xml (Caused by SSLError(SSLError(1, u'[SSL: CERTIFICATE_VERIFY_FAILED] certificate verify failed (_ssl.c:661)'),))
2021-12-20 01:26:27,558 - octoprint.plugins.announcements - ERROR - Could not fetch channel _plugins from https://plugins.octoprint.org/feed.xml: HTTPSConnectionPool(host='plugins.octoprint.org', port=443): Max retries exceeded with url: /feed.xml (Caused by SSLError(SSLError(1, u'[SSL: CERTIFICATE_VERIFY_FAILED] certificate verify failed (_ssl.c:661)'),))
Traceback (most recent call last):
  File "/opt/octoprint/venv/lib/python2.7/site-packages/OctoPrint-1.3.6-py2.7.egg/octoprint/plugins/announcements/__init__.py", line 355, in _get_channel_data_from_network
    r = requests.get(url, timeout=30)
  File "/opt/octoprint/venv/lib/python2.7/site-packages/requests-2.18.4-py2.7.egg/requests/api.py", line 72, in get
    return request('get', url, params=params, **kwargs)
  File "/opt/octoprint/venv/lib/python2.7/site-packages/requests-2.18.4-py2.7.egg/requests/api.py", line 58, in request
    return session.request(method=method, url=url, **kwargs)
  File "/opt/octoprint/venv/lib/python2.7/site-packages/requests-2.18.4-py2.7.egg/requests/sessions.py", line 508, in request
    resp = self.send(prep, **send_kwargs)
  File "/opt/octoprint/venv/lib/python2.7/site-packages/requests-2.18.4-py2.7.egg/requests/sessions.py", line 618, in send
    r = adapter.send(request, **kwargs)
  File "/opt/octoprint/venv/lib/python2.7/site-packages/requests-2.18.4-py2.7.egg/requests/adapters.py", line 506, in send
    raise SSLError(e, request=request)
SSLError: HTTPSConnectionPool(host='plugins.octoprint.org', port=443): Max retries exceeded with url: /feed.xml (Caused by SSLError(SSLError(1, u'[SSL: CERTIFICATE_VERIFY_FAILED] certificate verify failed (_ssl.c:661)'),))
2021-12-20 01:26:27,676 - octoprint.plugins.announcements - ERROR - Could not fetch channel _octopi from https://octoprint.org/feeds/octopi.xml: HTTPSConnectionPool(host='octoprint.org', port=443): Max retries exceeded with url: /feeds/octopi.xml (Caused by SSLError(SSLError(1, u'[SSL: CERTIFICATE_VERIFY_FAILED] certificate verify failed (_ssl.c:661)'),))
Traceback (most recent call last):
  File "/opt/octoprint/venv/lib/python2.7/site-packages/OctoPrint-1.3.6-py2.7.egg/octoprint/plugins/announcements/__init__.py", line 355, in _get_channel_data_from_network
    r = requests.get(url, timeout=30)
  File "/opt/octoprint/venv/lib/python2.7/site-packages/requests-2.18.4-py2.7.egg/requests/api.py", line 72, in get
    return request('get', url, params=params, **kwargs)
  File "/opt/octoprint/venv/lib/python2.7/site-packages/requests-2.18.4-py2.7.egg/requests/api.py", line 58, in request
    return session.request(method=method, url=url, **kwargs)
  File "/opt/octoprint/venv/lib/python2.7/site-packages/requests-2.18.4-py2.7.egg/requests/sessions.py", line 508, in request
    resp = self.send(prep, **send_kwargs)
  File "/opt/octoprint/venv/lib/python2.7/site-packages/requests-2.18.4-py2.7.egg/requests/sessions.py", line 618, in send
    r = adapter.send(request, **kwargs)
  File "/opt/octoprint/venv/lib/python2.7/site-packages/requests-2.18.4-py2.7.egg/requests/adapters.py", line 506, in send
    raise SSLError(e, request=request)
SSLError: HTTPSConnectionPool(host='octoprint.org', port=443): Max retries exceeded with url: /feeds/octopi.xml (Caused by SSLError(SSLError(1, u'[SSL: CERTIFICATE_VERIFY_FAILED] certificate verify failed (_ssl.c:661)'),))
2021-12-20 01:26:27,677 - octoprint.plugins.announcements - ERROR - Could not fetch channel _octopi from https://octoprint.org/feeds/octopi.xml: HTTPSConnectionPool(host='octoprint.org', port=443): Max retries exceeded with url: /feeds/octopi.xml (Caused by SSLError(SSLError(1, u'[SSL: CERTIFICATE_VERIFY_FAILED] certificate verify failed (_ssl.c:661)'),))
Traceback (most recent call last):
  File "/opt/octoprint/venv/lib/python2.7/site-packages/OctoPrint-1.3.6-py2.7.egg/octoprint/plugins/announcements/__init__.py", line 355, in _get_channel_data_from_network
    r = requests.get(url, timeout=30)
  File "/opt/octoprint/venv/lib/python2.7/site-packages/requests-2.18.4-py2.7.egg/requests/api.py", line 72, in get
    return request('get', url, params=params, **kwargs)
  File "/opt/octoprint/venv/lib/python2.7/site-packages/requests-2.18.4-py2.7.egg/requests/api.py", line 58, in request
    return session.request(method=method, url=url, **kwargs)
  File "/opt/octoprint/venv/lib/python2.7/site-packages/requests-2.18.4-py2.7.egg/requests/sessions.py", line 508, in request
    resp = self.send(prep, **send_kwargs)
  File "/opt/octoprint/venv/lib/python2.7/site-packages/requests-2.18.4-py2.7.egg/requests/sessions.py", line 618, in send
    r = adapter.send(request, **kwargs)
  File "/opt/octoprint/venv/lib/python2.7/site-packages/requests-2.18.4-py2.7.egg/requests/adapters.py", line 506, in send
    raise SSLError(e, request=request)
SSLError: HTTPSConnectionPool(host='octoprint.org', port=443): Max retries exceeded with url: /feeds/octopi.xml (Caused by SSLError(SSLError(1, u'[SSL: CERTIFICATE_VERIFY_FAILED] certificate verify failed (_ssl.c:661)'),))
2021-12-20 01:32:01,772 - octoprint.server - INFO - Shutting down...
2021-12-20 01:32:02,068 - octoprint.events - INFO - Processing shutdown event, this will be our last event
2021-12-20 01:32:02,072 - octoprint.events - INFO - Event loop shut down
2021-12-20 01:32:02,075 - octoprint.server - INFO - Goodbye!
2021-12-20 01:32:04,140 - octoprint.startup - INFO - ******************************************************************************
2021-12-20 01:32:04,141 - octoprint.startup - INFO - Starting OctoPrint 1.3.6
2021-12-20 01:32:04,142 - octoprint.startup - INFO - ******************************************************************************
2021-12-20 01:32:04,168 - octoprint.plugin.core - INFO - Loading plugins from /opt/octoprint/venv/lib/python2.7/site-packages/OctoPrint-1.3.6-py2.7.egg/octoprint/plugins, /home/octoprint/.octoprint/plugins and installed plugin packages...
2021-12-20 01:32:04,175 - octoprint.util.connectivity_checker - INFO - Connectivity changed from offline to online
2021-12-20 01:32:04,656 - octoprint.plugin.core - WARNING - Plugin "OctoPi Support Plugin" did not pass check
2021-12-20 01:32:04,674 - octoprint.plugins.discovery - INFO - pybonjour is not installed, Zeroconf Discovery won't be available
2021-12-20 01:32:04,677 - octoprint.plugin.core - INFO - Found 7 plugin(s) providing 7 mixin implementations, 4 hook handlers
2021-12-20 01:32:04,712 - octoprint.server - INFO - Intermediary server started
2021-12-20 01:32:04,714 - octoprint.plugin.core - INFO - Loading plugins from /opt/octoprint/venv/lib/python2.7/site-packages/OctoPrint-1.3.6-py2.7.egg/octoprint/plugins, /home/octoprint/.octoprint/plugins and installed plugin packages...
2021-12-20 01:32:04,715 - octoprint.plugin.core - WARNING - Plugin "OctoPi Support Plugin" did not pass check
2021-12-20 01:32:04,731 - octoprint.plugin.core - INFO - Found 7 plugin(s) providing 7 mixin implementations, 4 hook handlers
2021-12-20 01:32:04,748 - octoprint.filemanager.storage - INFO - Initializing the file metadata for /home/octoprint/.octoprint/uploads...
2021-12-20 01:32:04,901 - octoprint.filemanager.storage - INFO - ... file metadata for /home/octoprint/.octoprint/uploads initialized successfully.
2021-12-20 01:32:04,917 - octoprint.plugins.softwareupdate - INFO - Loaded version cache from disk
2021-12-20 01:32:05,314 - octoprint.util.pip - INFO - Using "/opt/octoprint/venv/bin/python -m pip" as command to invoke pip
2021-12-20 01:32:05,700 - octoprint.util.pip - INFO - Version of pip is 9.0.1
2021-12-20 01:32:05,703 - octoprint.plugin.core - INFO - Initialized 7 plugin implementation(s)
2021-12-20 01:32:05,706 - octoprint.plugin.core - INFO - 7 plugin(s) registered with the system:
|  Announcement Plugin (bundled) = /opt/octoprint/venv/lib/python2.7/site-packages/OctoPrint-1.3.6-py2.7.egg/octoprint/plugins/announcements
|  Core Wizard (bundled) = /opt/octoprint/venv/lib/python2.7/site-packages/OctoPrint-1.3.6-py2.7.egg/octoprint/plugins/corewizard
|  CuraEngine (<= 15.04) (bundled) = /opt/octoprint/venv/lib/python2.7/site-packages/OctoPrint-1.3.6-py2.7.egg/octoprint/plugins/cura
|  Discovery (bundled) = /opt/octoprint/venv/lib/python2.7/site-packages/OctoPrint-1.3.6-py2.7.egg/octoprint/plugins/discovery
|  Plugin Manager (bundled) = /opt/octoprint/venv/lib/python2.7/site-packages/OctoPrint-1.3.6-py2.7.egg/octoprint/plugins/pluginmanager
|  Software Update (bundled) = /opt/octoprint/venv/lib/python2.7/site-packages/OctoPrint-1.3.6-py2.7.egg/octoprint/plugins/softwareupdate
|  Virtual Printer (bundled) = /opt/octoprint/venv/lib/python2.7/site-packages/OctoPrint-1.3.6-py2.7.egg/octoprint/plugins/virtual_printer
2021-12-20 01:32:06,102 - octoprint.environment - INFO - Detected environment is Python 2.7.14 under Linux (linux2). Details:
|  hardware:
|    cores: 4
|    freq: unknown
|    ram: 2082197504
|  os:
|    id: linux
|    platform: linux2
|  python:
|    pip: 9.0.1
|    version: 2.7.14
|    virtualenv: /opt/octoprint/venv
2021-12-20 01:32:06,113 - octoprint.server - INFO - Reset webasset folder /home/octoprint/.octoprint/generated/webassets...
2021-12-20 01:32:06,124 - octoprint.server - INFO - Reset webasset folder /home/octoprint/.octoprint/generated/.webassets-cache...
2021-12-20 01:32:06,190 - octoprint.server - INFO - Shutting down intermediary server...
2021-12-20 01:32:06,224 - octoprint.server - INFO - Intermediary server shut down
2021-12-20 01:32:06,225 - octoprint.events - INFO - Processing startup event, this is our first event
2021-12-20 01:32:06,227 - octoprint.events - INFO - Adding 1 events to queue that were held back before startup event
2021-12-20 01:32:06,229 - octoprint.filemanager - INFO - Adding backlog items from all storage types to analysis queue...
2021-12-20 01:32:06,309 - octoprint.filemanager - INFO - Added 0 items from storage type "local" to analysis queue
2021-12-20 01:32:06,338 - octoprint.plugins.discovery - INFO - Registered OctoPrint instance on 5db76fd7d8c9 for SSDP
2021-12-20 01:32:06,340 - octoprint.server - INFO - Listening on http://0.0.0.0:5000
2021-12-20 01:32:06,378 - octoprint.plugins.pluginmanager - ERROR - Could not fetch plugins from repository at https://plugins.octoprint.org/plugins.json: HTTPSConnectionPool(host='plugins.octoprint.org', port=443): Max retries exceeded with url: /plugins.json (Caused by SSLError(SSLError(1, u'[SSL: CERTIFICATE_VERIFY_FAILED] certificate verify failed (_ssl.c:661)'),))
Traceback (most recent call last):
  File "/opt/octoprint/venv/lib/python2.7/site-packages/OctoPrint-1.3.6-py2.7.egg/octoprint/plugins/pluginmanager/__init__.py", line 738, in _fetch_repository_from_url
    r = requests.get(repository_url, timeout=30)
  File "/opt/octoprint/venv/lib/python2.7/site-packages/requests-2.18.4-py2.7.egg/requests/api.py", line 72, in get
    return request('get', url, params=params, **kwargs)
  File "/opt/octoprint/venv/lib/python2.7/site-packages/requests-2.18.4-py2.7.egg/requests/api.py", line 58, in request
    return session.request(method=method, url=url, **kwargs)
  File "/opt/octoprint/venv/lib/python2.7/site-packages/requests-2.18.4-py2.7.egg/requests/sessions.py", line 508, in request
    resp = self.send(prep, **send_kwargs)
  File "/opt/octoprint/venv/lib/python2.7/site-packages/requests-2.18.4-py2.7.egg/requests/sessions.py", line 618, in send
    r = adapter.send(request, **kwargs)
  File "/opt/octoprint/venv/lib/python2.7/site-packages/requests-2.18.4-py2.7.egg/requests/adapters.py", line 506, in send
    raise SSLError(e, request=request)
SSLError: HTTPSConnectionPool(host='plugins.octoprint.org', port=443): Max retries exceeded with url: /plugins.json (Caused by SSLError(SSLError(1, u'[SSL: CERTIFICATE_VERIFY_FAILED] certificate verify failed (_ssl.c:661)'),))
2021-12-20 01:32:06,449 - octoprint.plugins.announcements - ERROR - Could not fetch channel _important from https://octoprint.org/feeds/important.xml: HTTPSConnectionPool(host='octoprint.org', port=443): Max retries exceeded with url: /feeds/important.xml (Caused by SSLError(SSLError(1, u'[SSL: CERTIFICATE_VERIFY_FAILED] certificate verify failed (_ssl.c:661)'),))
Traceback (most recent call last):
  File "/opt/octoprint/venv/lib/python2.7/site-packages/OctoPrint-1.3.6-py2.7.egg/octoprint/plugins/announcements/__init__.py", line 355, in _get_channel_data_from_network
    r = requests.get(url, timeout=30)
  File "/opt/octoprint/venv/lib/python2.7/site-packages/requests-2.18.4-py2.7.egg/requests/api.py", line 72, in get
    return request('get', url, params=params, **kwargs)
  File "/opt/octoprint/venv/lib/python2.7/site-packages/requests-2.18.4-py2.7.egg/requests/api.py", line 58, in request
    return session.request(method=method, url=url, **kwargs)
  File "/opt/octoprint/venv/lib/python2.7/site-packages/requests-2.18.4-py2.7.egg/requests/sessions.py", line 508, in request
    resp = self.send(prep, **send_kwargs)
  File "/opt/octoprint/venv/lib/python2.7/site-packages/requests-2.18.4-py2.7.egg/requests/sessions.py", line 618, in send
    r = adapter.send(request, **kwargs)
  File "/opt/octoprint/venv/lib/python2.7/site-packages/requests-2.18.4-py2.7.egg/requests/adapters.py", line 506, in send
    raise SSLError(e, request=request)
SSLError: HTTPSConnectionPool(host='octoprint.org', port=443): Max retries exceeded with url: /feeds/important.xml (Caused by SSLError(SSLError(1, u'[SSL: CERTIFICATE_VERIFY_FAILED] certificate verify failed (_ssl.c:661)'),))
2021-12-20 01:32:06,483 - octoprint.plugins.announcements - ERROR - Could not fetch channel _important from https://octoprint.org/feeds/important.xml: HTTPSConnectionPool(host='octoprint.org', port=443): Max retries exceeded with url: /feeds/important.xml (Caused by SSLError(SSLError(1, u'[SSL: CERTIFICATE_VERIFY_FAILED] certificate verify failed (_ssl.c:661)'),))
Traceback (most recent call last):
  File "/opt/octoprint/venv/lib/python2.7/site-packages/OctoPrint-1.3.6-py2.7.egg/octoprint/plugins/announcements/__init__.py", line 355, in _get_channel_data_from_network
    r = requests.get(url, timeout=30)
  File "/opt/octoprint/venv/lib/python2.7/site-packages/requests-2.18.4-py2.7.egg/requests/api.py", line 72, in get
    return request('get', url, params=params, **kwargs)
  File "/opt/octoprint/venv/lib/python2.7/site-packages/requests-2.18.4-py2.7.egg/requests/api.py", line 58, in request
    return session.request(method=method, url=url, **kwargs)
  File "/opt/octoprint/venv/lib/python2.7/site-packages/requests-2.18.4-py2.7.egg/requests/sessions.py", line 508, in request
    resp = self.send(prep, **send_kwargs)
  File "/opt/octoprint/venv/lib/python2.7/site-packages/requests-2.18.4-py2.7.egg/requests/sessions.py", line 618, in send
    r = adapter.send(request, **kwargs)
  File "/opt/octoprint/venv/lib/python2.7/site-packages/requests-2.18.4-py2.7.egg/requests/adapters.py", line 506, in send
    raise SSLError(e, request=request)
SSLError: HTTPSConnectionPool(host='octoprint.org', port=443): Max retries exceeded with url: /feeds/important.xml (Caused by SSLError(SSLError(1, u'[SSL: CERTIFICATE_VERIFY_FAILED] certificate verify failed (_ssl.c:661)'),))
2021-12-20 01:32:06,571 - octoprint.plugins.pluginmanager - ERROR - Could not fetch plugins from repository at https://plugins.octoprint.org/plugins.json: HTTPSConnectionPool(host='plugins.octoprint.org', port=443): Max retries exceeded with url: /plugins.json (Caused by SSLError(SSLError(1, u'[SSL: CERTIFICATE_VERIFY_FAILED] certificate verify failed (_ssl.c:661)'),))
Traceback (most recent call last):
  File "/opt/octoprint/venv/lib/python2.7/site-packages/OctoPrint-1.3.6-py2.7.egg/octoprint/plugins/pluginmanager/__init__.py", line 738, in _fetch_repository_from_url
    r = requests.get(repository_url, timeout=30)
  File "/opt/octoprint/venv/lib/python2.7/site-packages/requests-2.18.4-py2.7.egg/requests/api.py", line 72, in get
    return request('get', url, params=params, **kwargs)
  File "/opt/octoprint/venv/lib/python2.7/site-packages/requests-2.18.4-py2.7.egg/requests/api.py", line 58, in request
    return session.request(method=method, url=url, **kwargs)
  File "/opt/octoprint/venv/lib/python2.7/site-packages/requests-2.18.4-py2.7.egg/requests/sessions.py", line 508, in request
    resp = self.send(prep, **send_kwargs)
  File "/opt/octoprint/venv/lib/python2.7/site-packages/requests-2.18.4-py2.7.egg/requests/sessions.py", line 618, in send
    r = adapter.send(request, **kwargs)
  File "/opt/octoprint/venv/lib/python2.7/site-packages/requests-2.18.4-py2.7.egg/requests/adapters.py", line 506, in send
    raise SSLError(e, request=request)
SSLError: HTTPSConnectionPool(host='plugins.octoprint.org', port=443): Max retries exceeded with url: /plugins.json (Caused by SSLError(SSLError(1, u'[SSL: CERTIFICATE_VERIFY_FAILED] certificate verify failed (_ssl.c:661)'),))
2021-12-20 01:32:06,600 - octoprint.plugins.pluginmanager - ERROR - Could not fetch notices from https://plugins.octoprint.org/notices.json: HTTPSConnectionPool(host='plugins.octoprint.org', port=443): Max retries exceeded with url: /notices.json (Caused by SSLError(SSLError(1, u'[SSL: CERTIFICATE_VERIFY_FAILED] certificate verify failed (_ssl.c:661)'),))
Traceback (most recent call last):
  File "/opt/octoprint/venv/lib/python2.7/site-packages/OctoPrint-1.3.6-py2.7.egg/octoprint/plugins/pluginmanager/__init__.py", line 812, in _fetch_notices_from_url
    r = requests.get(notices_url, timeout=30)
  File "/opt/octoprint/venv/lib/python2.7/site-packages/requests-2.18.4-py2.7.egg/requests/api.py", line 72, in get
    return request('get', url, params=params, **kwargs)
  File "/opt/octoprint/venv/lib/python2.7/site-packages/requests-2.18.4-py2.7.egg/requests/api.py", line 58, in request
    return session.request(method=method, url=url, **kwargs)
  File "/opt/octoprint/venv/lib/python2.7/site-packages/requests-2.18.4-py2.7.egg/requests/sessions.py", line 508, in request
    resp = self.send(prep, **send_kwargs)
  File "/opt/octoprint/venv/lib/python2.7/site-packages/requests-2.18.4-py2.7.egg/requests/sessions.py", line 618, in send
    r = adapter.send(request, **kwargs)
  File "/opt/octoprint/venv/lib/python2.7/site-packages/requests-2.18.4-py2.7.egg/requests/adapters.py", line 506, in send
    raise SSLError(e, request=request)
SSLError: HTTPSConnectionPool(host='plugins.octoprint.org', port=443): Max retries exceeded with url: /notices.json (Caused by SSLError(SSLError(1, u'[SSL: CERTIFICATE_VERIFY_FAILED] certificate verify failed (_ssl.c:661)'),))
2021-12-20 01:32:06,606 - octoprint.plugins.announcements - ERROR - Could not fetch channel _releases from https://octoprint.org/feeds/releases.xml: HTTPSConnectionPool(host='octoprint.org', port=443): Max retries exceeded with url: /feeds/releases.xml (Caused by SSLError(SSLError(1, u'[SSL: CERTIFICATE_VERIFY_FAILED] certificate verify failed (_ssl.c:661)'),))
Traceback (most recent call last):
  File "/opt/octoprint/venv/lib/python2.7/site-packages/OctoPrint-1.3.6-py2.7.egg/octoprint/plugins/announcements/__init__.py", line 355, in _get_channel_data_from_network
    r = requests.get(url, timeout=30)
  File "/opt/octoprint/venv/lib/python2.7/site-packages/requests-2.18.4-py2.7.egg/requests/api.py", line 72, in get
    return request('get', url, params=params, **kwargs)
  File "/opt/octoprint/venv/lib/python2.7/site-packages/requests-2.18.4-py2.7.egg/requests/api.py", line 58, in request
    return session.request(method=method, url=url, **kwargs)
  File "/opt/octoprint/venv/lib/python2.7/site-packages/requests-2.18.4-py2.7.egg/requests/sessions.py", line 508, in request
    resp = self.send(prep, **send_kwargs)
  File "/opt/octoprint/venv/lib/python2.7/site-packages/requests-2.18.4-py2.7.egg/requests/sessions.py", line 618, in send
    r = adapter.send(request, **kwargs)
  File "/opt/octoprint/venv/lib/python2.7/site-packages/requests-2.18.4-py2.7.egg/requests/adapters.py", line 506, in send
    raise SSLError(e, request=request)
SSLError: HTTPSConnectionPool(host='octoprint.org', port=443): Max retries exceeded with url: /feeds/releases.xml (Caused by SSLError(SSLError(1, u'[SSL: CERTIFICATE_VERIFY_FAILED] certificate verify failed (_ssl.c:661)'),))
2021-12-20 01:32:06,617 - octoprint.plugins.announcements - ERROR - Could not fetch channel _releases from https://octoprint.org/feeds/releases.xml: HTTPSConnectionPool(host='octoprint.org', port=443): Max retries exceeded with url: /feeds/releases.xml (Caused by SSLError(SSLError(1, u'[SSL: CERTIFICATE_VERIFY_FAILED] certificate verify failed (_ssl.c:661)'),))
Traceback (most recent call last):
  File "/opt/octoprint/venv/lib/python2.7/site-packages/OctoPrint-1.3.6-py2.7.egg/octoprint/plugins/announcements/__init__.py", line 355, in _get_channel_data_from_network
    r = requests.get(url, timeout=30)
  File "/opt/octoprint/venv/lib/python2.7/site-packages/requests-2.18.4-py2.7.egg/requests/api.py", line 72, in get
    return request('get', url, params=params, **kwargs)
  File "/opt/octoprint/venv/lib/python2.7/site-packages/requests-2.18.4-py2.7.egg/requests/api.py", line 58, in request
    return session.request(method=method, url=url, **kwargs)
  File "/opt/octoprint/venv/lib/python2.7/site-packages/requests-2.18.4-py2.7.egg/requests/sessions.py", line 508, in request
    resp = self.send(prep, **send_kwargs)
  File "/opt/octoprint/venv/lib/python2.7/site-packages/requests-2.18.4-py2.7.egg/requests/sessions.py", line 618, in send
    r = adapter.send(request, **kwargs)
  File "/opt/octoprint/venv/lib/python2.7/site-packages/requests-2.18.4-py2.7.egg/requests/adapters.py", line 506, in send
    raise SSLError(e, request=request)
SSLError: HTTPSConnectionPool(host='octoprint.org', port=443): Max retries exceeded with url: /feeds/releases.xml (Caused by SSLError(SSLError(1, u'[SSL: CERTIFICATE_VERIFY_FAILED] certificate verify failed (_ssl.c:661)'),))
2021-12-20 01:32:06,682 - octoprint.plugins.pluginmanager - ERROR - Could not fetch notices from https://plugins.octoprint.org/notices.json: HTTPSConnectionPool(host='plugins.octoprint.org', port=443): Max retries exceeded with url: /notices.json (Caused by SSLError(SSLError(1, u'[SSL: CERTIFICATE_VERIFY_FAILED] certificate verify failed (_ssl.c:661)'),))
Traceback (most recent call last):
  File "/opt/octoprint/venv/lib/python2.7/site-packages/OctoPrint-1.3.6-py2.7.egg/octoprint/plugins/pluginmanager/__init__.py", line 812, in _fetch_notices_from_url
    r = requests.get(notices_url, timeout=30)
  File "/opt/octoprint/venv/lib/python2.7/site-packages/requests-2.18.4-py2.7.egg/requests/api.py", line 72, in get
    return request('get', url, params=params, **kwargs)
  File "/opt/octoprint/venv/lib/python2.7/site-packages/requests-2.18.4-py2.7.egg/requests/api.py", line 58, in request
    return session.request(method=method, url=url, **kwargs)
  File "/opt/octoprint/venv/lib/python2.7/site-packages/requests-2.18.4-py2.7.egg/requests/sessions.py", line 508, in request
    resp = self.send(prep, **send_kwargs)
  File "/opt/octoprint/venv/lib/python2.7/site-packages/requests-2.18.4-py2.7.egg/requests/sessions.py", line 618, in send
    r = adapter.send(request, **kwargs)
  File "/opt/octoprint/venv/lib/python2.7/site-packages/requests-2.18.4-py2.7.egg/requests/adapters.py", line 506, in send
    raise SSLError(e, request=request)
SSLError: HTTPSConnectionPool(host='plugins.octoprint.org', port=443): Max retries exceeded with url: /notices.json (Caused by SSLError(SSLError(1, u'[SSL: CERTIFICATE_VERIFY_FAILED] certificate verify failed (_ssl.c:661)'),))
2021-12-20 01:32:06,718 - octoprint.plugins.announcements - ERROR - Could not fetch channel _blog from https://octoprint.org/feeds/octoblog.xml: HTTPSConnectionPool(host='octoprint.org', port=443): Max retries exceeded with url: /feeds/octoblog.xml (Caused by SSLError(SSLError(1, u'[SSL: CERTIFICATE_VERIFY_FAILED] certificate verify failed (_ssl.c:661)'),))
Traceback (most recent call last):
  File "/opt/octoprint/venv/lib/python2.7/site-packages/OctoPrint-1.3.6-py2.7.egg/octoprint/plugins/announcements/__init__.py", line 355, in _get_channel_data_from_network
    r = requests.get(url, timeout=30)
  File "/opt/octoprint/venv/lib/python2.7/site-packages/requests-2.18.4-py2.7.egg/requests/api.py", line 72, in get
    return request('get', url, params=params, **kwargs)
  File "/opt/octoprint/venv/lib/python2.7/site-packages/requests-2.18.4-py2.7.egg/requests/api.py", line 58, in request
    return session.request(method=method, url=url, **kwargs)
  File "/opt/octoprint/venv/lib/python2.7/site-packages/requests-2.18.4-py2.7.egg/requests/sessions.py", line 508, in request
    resp = self.send(prep, **send_kwargs)
  File "/opt/octoprint/venv/lib/python2.7/site-packages/requests-2.18.4-py2.7.egg/requests/sessions.py", line 618, in send
    r = adapter.send(request, **kwargs)
  File "/opt/octoprint/venv/lib/python2.7/site-packages/requests-2.18.4-py2.7.egg/requests/adapters.py", line 506, in send
    raise SSLError(e, request=request)
SSLError: HTTPSConnectionPool(host='octoprint.org', port=443): Max retries exceeded with url: /feeds/octoblog.xml (Caused by SSLError(SSLError(1, u'[SSL: CERTIFICATE_VERIFY_FAILED] certificate verify failed (_ssl.c:661)'),))
2021-12-20 01:32:06,721 - octoprint.plugins.announcements - ERROR - Could not fetch channel _blog from https://octoprint.org/feeds/octoblog.xml: HTTPSConnectionPool(host='octoprint.org', port=443): Max retries exceeded with url: /feeds/octoblog.xml (Caused by SSLError(SSLError(1, u'[SSL: CERTIFICATE_VERIFY_FAILED] certificate verify failed (_ssl.c:661)'),))
Traceback (most recent call last):
  File "/opt/octoprint/venv/lib/python2.7/site-packages/OctoPrint-1.3.6-py2.7.egg/octoprint/plugins/announcements/__init__.py", line 355, in _get_channel_data_from_network
    r = requests.get(url, timeout=30)
  File "/opt/octoprint/venv/lib/python2.7/site-packages/requests-2.18.4-py2.7.egg/requests/api.py", line 72, in get
    return request('get', url, params=params, **kwargs)
  File "/opt/octoprint/venv/lib/python2.7/site-packages/requests-2.18.4-py2.7.egg/requests/api.py", line 58, in request
    return session.request(method=method, url=url, **kwargs)
  File "/opt/octoprint/venv/lib/python2.7/site-packages/requests-2.18.4-py2.7.egg/requests/sessions.py", line 508, in request
    resp = self.send(prep, **send_kwargs)
  File "/opt/octoprint/venv/lib/python2.7/site-packages/requests-2.18.4-py2.7.egg/requests/sessions.py", line 618, in send
    r = adapter.send(request, **kwargs)
  File "/opt/octoprint/venv/lib/python2.7/site-packages/requests-2.18.4-py2.7.egg/requests/adapters.py", line 506, in send
    raise SSLError(e, request=request)
SSLError: HTTPSConnectionPool(host='octoprint.org', port=443): Max retries exceeded with url: /feeds/octoblog.xml (Caused by SSLError(SSLError(1, u'[SSL: CERTIFICATE_VERIFY_FAILED] certificate verify failed (_ssl.c:661)'),))
2021-12-20 01:32:06,837 - octoprint.plugins.announcements - ERROR - Could not fetch channel _plugins from https://plugins.octoprint.org/feed.xml: HTTPSConnectionPool(host='plugins.octoprint.org', port=443): Max retries exceeded with url: /feed.xml (Caused by SSLError(SSLError(1, u'[SSL: CERTIFICATE_VERIFY_FAILED] certificate verify failed (_ssl.c:661)'),))
Traceback (most recent call last):
  File "/opt/octoprint/venv/lib/python2.7/site-packages/OctoPrint-1.3.6-py2.7.egg/octoprint/plugins/announcements/__init__.py", line 355, in _get_channel_data_from_network
    r = requests.get(url, timeout=30)
  File "/opt/octoprint/venv/lib/python2.7/site-packages/requests-2.18.4-py2.7.egg/requests/api.py", line 72, in get
    return request('get', url, params=params, **kwargs)
  File "/opt/octoprint/venv/lib/python2.7/site-packages/requests-2.18.4-py2.7.egg/requests/api.py", line 58, in request
    return session.request(method=method, url=url, **kwargs)
  File "/opt/octoprint/venv/lib/python2.7/site-packages/requests-2.18.4-py2.7.egg/requests/sessions.py", line 508, in request
    resp = self.send(prep, **send_kwargs)
  File "/opt/octoprint/venv/lib/python2.7/site-packages/requests-2.18.4-py2.7.egg/requests/sessions.py", line 618, in send
    r = adapter.send(request, **kwargs)
  File "/opt/octoprint/venv/lib/python2.7/site-packages/requests-2.18.4-py2.7.egg/requests/adapters.py", line 506, in send
    raise SSLError(e, request=request)
SSLError: HTTPSConnectionPool(host='plugins.octoprint.org', port=443): Max retries exceeded with url: /feed.xml (Caused by SSLError(SSLError(1, u'[SSL: CERTIFICATE_VERIFY_FAILED] certificate verify failed (_ssl.c:661)'),))
2021-12-20 01:32:06,840 - octoprint.plugins.announcements - ERROR - Could not fetch channel _plugins from https://plugins.octoprint.org/feed.xml: HTTPSConnectionPool(host='plugins.octoprint.org', port=443): Max retries exceeded with url: /feed.xml (Caused by SSLError(SSLError(1, u'[SSL: CERTIFICATE_VERIFY_FAILED] certificate verify failed (_ssl.c:661)'),))
Traceback (most recent call last):
  File "/opt/octoprint/venv/lib/python2.7/site-packages/OctoPrint-1.3.6-py2.7.egg/octoprint/plugins/announcements/__init__.py", line 355, in _get_channel_data_from_network
    r = requests.get(url, timeout=30)
  File "/opt/octoprint/venv/lib/python2.7/site-packages/requests-2.18.4-py2.7.egg/requests/api.py", line 72, in get
    return request('get', url, params=params, **kwargs)
  File "/opt/octoprint/venv/lib/python2.7/site-packages/requests-2.18.4-py2.7.egg/requests/api.py", line 58, in request
    return session.request(method=method, url=url, **kwargs)
  File "/opt/octoprint/venv/lib/python2.7/site-packages/requests-2.18.4-py2.7.egg/requests/sessions.py", line 508, in request
    resp = self.send(prep, **send_kwargs)
  File "/opt/octoprint/venv/lib/python2.7/site-packages/requests-2.18.4-py2.7.egg/requests/sessions.py", line 618, in send
    r = adapter.send(request, **kwargs)
  File "/opt/octoprint/venv/lib/python2.7/site-packages/requests-2.18.4-py2.7.egg/requests/adapters.py", line 506, in send
    raise SSLError(e, request=request)
SSLError: HTTPSConnectionPool(host='plugins.octoprint.org', port=443): Max retries exceeded with url: /feed.xml (Caused by SSLError(SSLError(1, u'[SSL: CERTIFICATE_VERIFY_FAILED] certificate verify failed (_ssl.c:661)'),))
2021-12-20 01:32:06,964 - octoprint.plugins.announcements - ERROR - Could not fetch channel _octopi from https://octoprint.org/feeds/octopi.xml: HTTPSConnectionPool(host='octoprint.org', port=443): Max retries exceeded with url: /feeds/octopi.xml (Caused by SSLError(SSLError(1, u'[SSL: CERTIFICATE_VERIFY_FAILED] certificate verify failed (_ssl.c:661)'),))
Traceback (most recent call last):
  File "/opt/octoprint/venv/lib/python2.7/site-packages/OctoPrint-1.3.6-py2.7.egg/octoprint/plugins/announcements/__init__.py", line 355, in _get_channel_data_from_network
    r = requests.get(url, timeout=30)
  File "/opt/octoprint/venv/lib/python2.7/site-packages/requests-2.18.4-py2.7.egg/requests/api.py", line 72, in get
    return request('get', url, params=params, **kwargs)
  File "/opt/octoprint/venv/lib/python2.7/site-packages/requests-2.18.4-py2.7.egg/requests/api.py", line 58, in request
    return session.request(method=method, url=url, **kwargs)
  File "/opt/octoprint/venv/lib/python2.7/site-packages/requests-2.18.4-py2.7.egg/requests/sessions.py", line 508, in request
    resp = self.send(prep, **send_kwargs)
  File "/opt/octoprint/venv/lib/python2.7/site-packages/requests-2.18.4-py2.7.egg/requests/sessions.py", line 618, in send
    r = adapter.send(request, **kwargs)
  File "/opt/octoprint/venv/lib/python2.7/site-packages/requests-2.18.4-py2.7.egg/requests/adapters.py", line 506, in send
    raise SSLError(e, request=request)
SSLError: HTTPSConnectionPool(host='octoprint.org', port=443): Max retries exceeded with url: /feeds/octopi.xml (Caused by SSLError(SSLError(1, u'[SSL: CERTIFICATE_VERIFY_FAILED] certificate verify failed (_ssl.c:661)'),))
2021-12-20 01:32:06,965 - octoprint.plugins.announcements - ERROR - Could not fetch channel _octopi from https://octoprint.org/feeds/octopi.xml: HTTPSConnectionPool(host='octoprint.org', port=443): Max retries exceeded with url: /feeds/octopi.xml (Caused by SSLError(SSLError(1, u'[SSL: CERTIFICATE_VERIFY_FAILED] certificate verify failed (_ssl.c:661)'),))
Traceback (most recent call last):
  File "/opt/octoprint/venv/lib/python2.7/site-packages/OctoPrint-1.3.6-py2.7.egg/octoprint/plugins/announcements/__init__.py", line 355, in _get_channel_data_from_network
    r = requests.get(url, timeout=30)
  File "/opt/octoprint/venv/lib/python2.7/site-packages/requests-2.18.4-py2.7.egg/requests/api.py", line 72, in get
    return request('get', url, params=params, **kwargs)
  File "/opt/octoprint/venv/lib/python2.7/site-packages/requests-2.18.4-py2.7.egg/requests/api.py", line 58, in request
    return session.request(method=method, url=url, **kwargs)
  File "/opt/octoprint/venv/lib/python2.7/site-packages/requests-2.18.4-py2.7.egg/requests/sessions.py", line 508, in request
    resp = self.send(prep, **send_kwargs)
  File "/opt/octoprint/venv/lib/python2.7/site-packages/requests-2.18.4-py2.7.egg/requests/sessions.py", line 618, in send
    r = adapter.send(request, **kwargs)
  File "/opt/octoprint/venv/lib/python2.7/site-packages/requests-2.18.4-py2.7.egg/requests/adapters.py", line 506, in send
    raise SSLError(e, request=request)
SSLError: HTTPSConnectionPool(host='octoprint.org', port=443): Max retries exceeded with url: /feeds/octopi.xml (Caused by SSLError(SSLError(1, u'[SSL: CERTIFICATE_VERIFY_FAILED] certificate verify failed (_ssl.c:661)'),))
