2021-11-15 20:50:06,763 - octoprint.server - INFO - --- Log roll over detected ---------------------------------------------------
2021-11-15 20:50:06,764 - octoprint.server - INFO - --- Log roll over detected ---------------------------------------------------
2021-11-15 20:50:06,765 - octoprint.server - INFO - OctoPrint 1.3.6
2021-11-15 20:50:06,766 - octoprint.server - INFO - OctoPrint 1.3.6
2021-11-15 20:50:06,767 - octoprint.plugin.core - INFO - 7 plugin(s) registered with the system:
|  Announcement Plugin (bundled) = /opt/octoprint/venv/lib/python2.7/site-packages/OctoPrint-1.3.6-py2.7.egg/octoprint/plugins/announcements
|  Core Wizard (bundled) = /opt/octoprint/venv/lib/python2.7/site-packages/OctoPrint-1.3.6-py2.7.egg/octoprint/plugins/corewizard
|  CuraEngine (<= 15.04) (bundled) = /opt/octoprint/venv/lib/python2.7/site-packages/OctoPrint-1.3.6-py2.7.egg/octoprint/plugins/cura
|  Discovery (bundled) = /opt/octoprint/venv/lib/python2.7/site-packages/OctoPrint-1.3.6-py2.7.egg/octoprint/plugins/discovery
|  Plugin Manager (bundled) = /opt/octoprint/venv/lib/python2.7/site-packages/OctoPrint-1.3.6-py2.7.egg/octoprint/plugins/pluginmanager
|  Software Update (bundled) = /opt/octoprint/venv/lib/python2.7/site-packages/OctoPrint-1.3.6-py2.7.egg/octoprint/plugins/softwareupdate
|  Virtual Printer (bundled) = /opt/octoprint/venv/lib/python2.7/site-packages/OctoPrint-1.3.6-py2.7.egg/octoprint/plugins/virtual_printer
2021-11-15 20:50:06,768 - octoprint.plugin.core - INFO - 7 plugin(s) registered with the system:
|  Announcement Plugin (bundled) = /opt/octoprint/venv/lib/python2.7/site-packages/OctoPrint-1.3.6-py2.7.egg/octoprint/plugins/announcements
|  Core Wizard (bundled) = /opt/octoprint/venv/lib/python2.7/site-packages/OctoPrint-1.3.6-py2.7.egg/octoprint/plugins/corewizard
|  CuraEngine (<= 15.04) (bundled) = /opt/octoprint/venv/lib/python2.7/site-packages/OctoPrint-1.3.6-py2.7.egg/octoprint/plugins/cura
|  Discovery (bundled) = /opt/octoprint/venv/lib/python2.7/site-packages/OctoPrint-1.3.6-py2.7.egg/octoprint/plugins/discovery
|  Plugin Manager (bundled) = /opt/octoprint/venv/lib/python2.7/site-packages/OctoPrint-1.3.6-py2.7.egg/octoprint/plugins/pluginmanager
|  Software Update (bundled) = /opt/octoprint/venv/lib/python2.7/site-packages/OctoPrint-1.3.6-py2.7.egg/octoprint/plugins/softwareupdate
|  Virtual Printer (bundled) = /opt/octoprint/venv/lib/python2.7/site-packages/OctoPrint-1.3.6-py2.7.egg/octoprint/plugins/virtual_printer
2021-11-15 20:50:06,770 - octoprint.environment - INFO - Detected environment is Python 2.7.14 under Linux (linux2). Details:
|  hardware:
|    cores: 4
|    freq: unknown
|    ram: 2082197504
|  os:
|    id: linux
|    platform: linux2
|  python:
|    pip: 9.0.1
|    version: 2.7.14
|    virtualenv: /opt/octoprint/venv
2021-11-15 20:50:06,772 - octoprint.server - INFO - ------------------------------------------------------------------------------
2021-11-15 20:50:06,773 - octoprint.environment - INFO - Detected environment is Python 2.7.14 under Linux (linux2). Details:
|  hardware:
|    cores: 4
|    freq: unknown
|    ram: 2082197504
|  os:
|    id: linux
|    platform: linux2
|  python:
|    pip: 9.0.1
|    version: 2.7.14
|    virtualenv: /opt/octoprint/venv
2021-11-15 20:50:06,750 - octoprint.util.connectivity_checker - INFO - Connectivity changed from online to offline
2021-11-15 20:50:06,775 - octoprint.server - INFO - ------------------------------------------------------------------------------
2021-11-15 20:50:06,746 - octoprint.util.connectivity_checker - INFO - Connectivity changed from online to offline
2021-11-15 21:35:06,803 - octoprint.util.connectivity_checker - INFO - Connectivity changed from offline to online
2021-11-15 21:35:06,803 - octoprint.util.connectivity_checker - INFO - Connectivity changed from offline to online
2021-11-15 21:35:06,916 - octoprint.plugins.announcements - ERROR - Could not fetch channel _important from https://octoprint.org/feeds/important.xml: HTTPSConnectionPool(host='octoprint.org', port=443): Max retries exceeded with url: /feeds/important.xml (Caused by SSLError(SSLError(1, u'[SSL: CERTIFICATE_VERIFY_FAILED] certificate verify failed (_ssl.c:661)'),))
Traceback (most recent call last):
  File "/opt/octoprint/venv/lib/python2.7/site-packages/OctoPrint-1.3.6-py2.7.egg/octoprint/plugins/announcements/__init__.py", line 355, in _get_channel_data_from_network
    r = requests.get(url, timeout=30)
  File "/opt/octoprint/venv/lib/python2.7/site-packages/requests-2.18.4-py2.7.egg/requests/api.py", line 72, in get
    return request('get', url, params=params, **kwargs)
  File "/opt/octoprint/venv/lib/python2.7/site-packages/requests-2.18.4-py2.7.egg/requests/api.py", line 58, in request
    return session.request(method=method, url=url, **kwargs)
  File "/opt/octoprint/venv/lib/python2.7/site-packages/requests-2.18.4-py2.7.egg/requests/sessions.py", line 508, in request
    resp = self.send(prep, **send_kwargs)
  File "/opt/octoprint/venv/lib/python2.7/site-packages/requests-2.18.4-py2.7.egg/requests/sessions.py", line 618, in send
    r = adapter.send(request, **kwargs)
  File "/opt/octoprint/venv/lib/python2.7/site-packages/requests-2.18.4-py2.7.egg/requests/adapters.py", line 506, in send
    raise SSLError(e, request=request)
SSLError: HTTPSConnectionPool(host='octoprint.org', port=443): Max retries exceeded with url: /feeds/important.xml (Caused by SSLError(SSLError(1, u'[SSL: CERTIFICATE_VERIFY_FAILED] certificate verify failed (_ssl.c:661)'),))
2021-11-15 21:35:06,916 - octoprint.plugins.announcements - ERROR - Could not fetch channel _important from https://octoprint.org/feeds/important.xml: HTTPSConnectionPool(host='octoprint.org', port=443): Max retries exceeded with url: /feeds/important.xml (Caused by SSLError(SSLError(1, u'[SSL: CERTIFICATE_VERIFY_FAILED] certificate verify failed (_ssl.c:661)'),))
Traceback (most recent call last):
  File "/opt/octoprint/venv/lib/python2.7/site-packages/OctoPrint-1.3.6-py2.7.egg/octoprint/plugins/announcements/__init__.py", line 355, in _get_channel_data_from_network
    r = requests.get(url, timeout=30)
  File "/opt/octoprint/venv/lib/python2.7/site-packages/requests-2.18.4-py2.7.egg/requests/api.py", line 72, in get
    return request('get', url, params=params, **kwargs)
  File "/opt/octoprint/venv/lib/python2.7/site-packages/requests-2.18.4-py2.7.egg/requests/api.py", line 58, in request
    return session.request(method=method, url=url, **kwargs)
  File "/opt/octoprint/venv/lib/python2.7/site-packages/requests-2.18.4-py2.7.egg/requests/sessions.py", line 508, in request
    resp = self.send(prep, **send_kwargs)
  File "/opt/octoprint/venv/lib/python2.7/site-packages/requests-2.18.4-py2.7.egg/requests/sessions.py", line 618, in send
    r = adapter.send(request, **kwargs)
  File "/opt/octoprint/venv/lib/python2.7/site-packages/requests-2.18.4-py2.7.egg/requests/adapters.py", line 506, in send
    raise SSLError(e, request=request)
SSLError: HTTPSConnectionPool(host='octoprint.org', port=443): Max retries exceeded with url: /feeds/important.xml (Caused by SSLError(SSLError(1, u'[SSL: CERTIFICATE_VERIFY_FAILED] certificate verify failed (_ssl.c:661)'),))
2021-11-15 21:35:06,923 - octoprint.plugins.pluginmanager - ERROR - Could not fetch plugins from repository at https://plugins.octoprint.org/plugins.json: HTTPSConnectionPool(host='plugins.octoprint.org', port=443): Max retries exceeded with url: /plugins.json (Caused by SSLError(SSLError(1, u'[SSL: CERTIFICATE_VERIFY_FAILED] certificate verify failed (_ssl.c:661)'),))
Traceback (most recent call last):
  File "/opt/octoprint/venv/lib/python2.7/site-packages/OctoPrint-1.3.6-py2.7.egg/octoprint/plugins/pluginmanager/__init__.py", line 738, in _fetch_repository_from_url
    r = requests.get(repository_url, timeout=30)
  File "/opt/octoprint/venv/lib/python2.7/site-packages/requests-2.18.4-py2.7.egg/requests/api.py", line 72, in get
    return request('get', url, params=params, **kwargs)
  File "/opt/octoprint/venv/lib/python2.7/site-packages/requests-2.18.4-py2.7.egg/requests/api.py", line 58, in request
    return session.request(method=method, url=url, **kwargs)
  File "/opt/octoprint/venv/lib/python2.7/site-packages/requests-2.18.4-py2.7.egg/requests/sessions.py", line 508, in request
    resp = self.send(prep, **send_kwargs)
  File "/opt/octoprint/venv/lib/python2.7/site-packages/requests-2.18.4-py2.7.egg/requests/sessions.py", line 618, in send
    r = adapter.send(request, **kwargs)
  File "/opt/octoprint/venv/lib/python2.7/site-packages/requests-2.18.4-py2.7.egg/requests/adapters.py", line 506, in send
    raise SSLError(e, request=request)
SSLError: HTTPSConnectionPool(host='plugins.octoprint.org', port=443): Max retries exceeded with url: /plugins.json (Caused by SSLError(SSLError(1, u'[SSL: CERTIFICATE_VERIFY_FAILED] certificate verify failed (_ssl.c:661)'),))
2021-11-15 21:35:06,922 - octoprint.plugins.pluginmanager - ERROR - Could not fetch plugins from repository at https://plugins.octoprint.org/plugins.json: HTTPSConnectionPool(host='plugins.octoprint.org', port=443): Max retries exceeded with url: /plugins.json (Caused by SSLError(SSLError(1, u'[SSL: CERTIFICATE_VERIFY_FAILED] certificate verify failed (_ssl.c:661)'),))
Traceback (most recent call last):
  File "/opt/octoprint/venv/lib/python2.7/site-packages/OctoPrint-1.3.6-py2.7.egg/octoprint/plugins/pluginmanager/__init__.py", line 738, in _fetch_repository_from_url
    r = requests.get(repository_url, timeout=30)
  File "/opt/octoprint/venv/lib/python2.7/site-packages/requests-2.18.4-py2.7.egg/requests/api.py", line 72, in get
    return request('get', url, params=params, **kwargs)
  File "/opt/octoprint/venv/lib/python2.7/site-packages/requests-2.18.4-py2.7.egg/requests/api.py", line 58, in request
    return session.request(method=method, url=url, **kwargs)
  File "/opt/octoprint/venv/lib/python2.7/site-packages/requests-2.18.4-py2.7.egg/requests/sessions.py", line 508, in request
    resp = self.send(prep, **send_kwargs)
  File "/opt/octoprint/venv/lib/python2.7/site-packages/requests-2.18.4-py2.7.egg/requests/sessions.py", line 618, in send
    r = adapter.send(request, **kwargs)
  File "/opt/octoprint/venv/lib/python2.7/site-packages/requests-2.18.4-py2.7.egg/requests/adapters.py", line 506, in send
    raise SSLError(e, request=request)
SSLError: HTTPSConnectionPool(host='plugins.octoprint.org', port=443): Max retries exceeded with url: /plugins.json (Caused by SSLError(SSLError(1, u'[SSL: CERTIFICATE_VERIFY_FAILED] certificate verify failed (_ssl.c:661)'),))
2021-11-15 21:35:06,998 - octoprint.plugins.announcements - ERROR - Could not fetch channel _releases from https://octoprint.org/feeds/releases.xml: HTTPSConnectionPool(host='octoprint.org', port=443): Max retries exceeded with url: /feeds/releases.xml (Caused by SSLError(SSLError(1, u'[SSL: CERTIFICATE_VERIFY_FAILED] certificate verify failed (_ssl.c:661)'),))
Traceback (most recent call last):
  File "/opt/octoprint/venv/lib/python2.7/site-packages/OctoPrint-1.3.6-py2.7.egg/octoprint/plugins/announcements/__init__.py", line 355, in _get_channel_data_from_network
    r = requests.get(url, timeout=30)
  File "/opt/octoprint/venv/lib/python2.7/site-packages/requests-2.18.4-py2.7.egg/requests/api.py", line 72, in get
    return request('get', url, params=params, **kwargs)
  File "/opt/octoprint/venv/lib/python2.7/site-packages/requests-2.18.4-py2.7.egg/requests/api.py", line 58, in request
    return session.request(method=method, url=url, **kwargs)
  File "/opt/octoprint/venv/lib/python2.7/site-packages/requests-2.18.4-py2.7.egg/requests/sessions.py", line 508, in request
    resp = self.send(prep, **send_kwargs)
  File "/opt/octoprint/venv/lib/python2.7/site-packages/requests-2.18.4-py2.7.egg/requests/sessions.py", line 618, in send
    r = adapter.send(request, **kwargs)
  File "/opt/octoprint/venv/lib/python2.7/site-packages/requests-2.18.4-py2.7.egg/requests/adapters.py", line 506, in send
    raise SSLError(e, request=request)
SSLError: HTTPSConnectionPool(host='octoprint.org', port=443): Max retries exceeded with url: /feeds/releases.xml (Caused by SSLError(SSLError(1, u'[SSL: CERTIFICATE_VERIFY_FAILED] certificate verify failed (_ssl.c:661)'),))
2021-11-15 21:35:06,998 - octoprint.plugins.announcements - ERROR - Could not fetch channel _releases from https://octoprint.org/feeds/releases.xml: HTTPSConnectionPool(host='octoprint.org', port=443): Max retries exceeded with url: /feeds/releases.xml (Caused by SSLError(SSLError(1, u'[SSL: CERTIFICATE_VERIFY_FAILED] certificate verify failed (_ssl.c:661)'),))
Traceback (most recent call last):
  File "/opt/octoprint/venv/lib/python2.7/site-packages/OctoPrint-1.3.6-py2.7.egg/octoprint/plugins/announcements/__init__.py", line 355, in _get_channel_data_from_network
    r = requests.get(url, timeout=30)
  File "/opt/octoprint/venv/lib/python2.7/site-packages/requests-2.18.4-py2.7.egg/requests/api.py", line 72, in get
    return request('get', url, params=params, **kwargs)
  File "/opt/octoprint/venv/lib/python2.7/site-packages/requests-2.18.4-py2.7.egg/requests/api.py", line 58, in request
    return session.request(method=method, url=url, **kwargs)
  File "/opt/octoprint/venv/lib/python2.7/site-packages/requests-2.18.4-py2.7.egg/requests/sessions.py", line 508, in request
    resp = self.send(prep, **send_kwargs)
  File "/opt/octoprint/venv/lib/python2.7/site-packages/requests-2.18.4-py2.7.egg/requests/sessions.py", line 618, in send
    r = adapter.send(request, **kwargs)
  File "/opt/octoprint/venv/lib/python2.7/site-packages/requests-2.18.4-py2.7.egg/requests/adapters.py", line 506, in send
    raise SSLError(e, request=request)
SSLError: HTTPSConnectionPool(host='octoprint.org', port=443): Max retries exceeded with url: /feeds/releases.xml (Caused by SSLError(SSLError(1, u'[SSL: CERTIFICATE_VERIFY_FAILED] certificate verify failed (_ssl.c:661)'),))
2021-11-15 21:35:07,002 - octoprint.plugins.pluginmanager - ERROR - Could not fetch notices from https://plugins.octoprint.org/notices.json: HTTPSConnectionPool(host='plugins.octoprint.org', port=443): Max retries exceeded with url: /notices.json (Caused by SSLError(SSLError(1, u'[SSL: CERTIFICATE_VERIFY_FAILED] certificate verify failed (_ssl.c:661)'),))
Traceback (most recent call last):
  File "/opt/octoprint/venv/lib/python2.7/site-packages/OctoPrint-1.3.6-py2.7.egg/octoprint/plugins/pluginmanager/__init__.py", line 812, in _fetch_notices_from_url
    r = requests.get(notices_url, timeout=30)
  File "/opt/octoprint/venv/lib/python2.7/site-packages/requests-2.18.4-py2.7.egg/requests/api.py", line 72, in get
    return request('get', url, params=params, **kwargs)
  File "/opt/octoprint/venv/lib/python2.7/site-packages/requests-2.18.4-py2.7.egg/requests/api.py", line 58, in request
    return session.request(method=method, url=url, **kwargs)
  File "/opt/octoprint/venv/lib/python2.7/site-packages/requests-2.18.4-py2.7.egg/requests/sessions.py", line 508, in request
    resp = self.send(prep, **send_kwargs)
  File "/opt/octoprint/venv/lib/python2.7/site-packages/requests-2.18.4-py2.7.egg/requests/sessions.py", line 618, in send
    r = adapter.send(request, **kwargs)
  File "/opt/octoprint/venv/lib/python2.7/site-packages/requests-2.18.4-py2.7.egg/requests/adapters.py", line 506, in send
    raise SSLError(e, request=request)
SSLError: HTTPSConnectionPool(host='plugins.octoprint.org', port=443): Max retries exceeded with url: /notices.json (Caused by SSLError(SSLError(1, u'[SSL: CERTIFICATE_VERIFY_FAILED] certificate verify failed (_ssl.c:661)'),))
2021-11-15 21:35:07,002 - octoprint.plugins.pluginmanager - ERROR - Could not fetch notices from https://plugins.octoprint.org/notices.json: HTTPSConnectionPool(host='plugins.octoprint.org', port=443): Max retries exceeded with url: /notices.json (Caused by SSLError(SSLError(1, u'[SSL: CERTIFICATE_VERIFY_FAILED] certificate verify failed (_ssl.c:661)'),))
Traceback (most recent call last):
  File "/opt/octoprint/venv/lib/python2.7/site-packages/OctoPrint-1.3.6-py2.7.egg/octoprint/plugins/pluginmanager/__init__.py", line 812, in _fetch_notices_from_url
    r = requests.get(notices_url, timeout=30)
  File "/opt/octoprint/venv/lib/python2.7/site-packages/requests-2.18.4-py2.7.egg/requests/api.py", line 72, in get
    return request('get', url, params=params, **kwargs)
  File "/opt/octoprint/venv/lib/python2.7/site-packages/requests-2.18.4-py2.7.egg/requests/api.py", line 58, in request
    return session.request(method=method, url=url, **kwargs)
  File "/opt/octoprint/venv/lib/python2.7/site-packages/requests-2.18.4-py2.7.egg/requests/sessions.py", line 508, in request
    resp = self.send(prep, **send_kwargs)
  File "/opt/octoprint/venv/lib/python2.7/site-packages/requests-2.18.4-py2.7.egg/requests/sessions.py", line 618, in send
    r = adapter.send(request, **kwargs)
  File "/opt/octoprint/venv/lib/python2.7/site-packages/requests-2.18.4-py2.7.egg/requests/adapters.py", line 506, in send
    raise SSLError(e, request=request)
SSLError: HTTPSConnectionPool(host='plugins.octoprint.org', port=443): Max retries exceeded with url: /notices.json (Caused by SSLError(SSLError(1, u'[SSL: CERTIFICATE_VERIFY_FAILED] certificate verify failed (_ssl.c:661)'),))
2021-11-15 21:35:07,068 - octoprint.plugins.announcements - ERROR - Could not fetch channel _blog from https://octoprint.org/feeds/octoblog.xml: HTTPSConnectionPool(host='octoprint.org', port=443): Max retries exceeded with url: /feeds/octoblog.xml (Caused by SSLError(SSLError(1, u'[SSL: CERTIFICATE_VERIFY_FAILED] certificate verify failed (_ssl.c:661)'),))
Traceback (most recent call last):
  File "/opt/octoprint/venv/lib/python2.7/site-packages/OctoPrint-1.3.6-py2.7.egg/octoprint/plugins/announcements/__init__.py", line 355, in _get_channel_data_from_network
    r = requests.get(url, timeout=30)
  File "/opt/octoprint/venv/lib/python2.7/site-packages/requests-2.18.4-py2.7.egg/requests/api.py", line 72, in get
    return request('get', url, params=params, **kwargs)
  File "/opt/octoprint/venv/lib/python2.7/site-packages/requests-2.18.4-py2.7.egg/requests/api.py", line 58, in request
    return session.request(method=method, url=url, **kwargs)
  File "/opt/octoprint/venv/lib/python2.7/site-packages/requests-2.18.4-py2.7.egg/requests/sessions.py", line 508, in request
    resp = self.send(prep, **send_kwargs)
  File "/opt/octoprint/venv/lib/python2.7/site-packages/requests-2.18.4-py2.7.egg/requests/sessions.py", line 618, in send
    r = adapter.send(request, **kwargs)
  File "/opt/octoprint/venv/lib/python2.7/site-packages/requests-2.18.4-py2.7.egg/requests/adapters.py", line 506, in send
    raise SSLError(e, request=request)
SSLError: HTTPSConnectionPool(host='octoprint.org', port=443): Max retries exceeded with url: /feeds/octoblog.xml (Caused by SSLError(SSLError(1, u'[SSL: CERTIFICATE_VERIFY_FAILED] certificate verify failed (_ssl.c:661)'),))
2021-11-15 21:35:07,098 - octoprint.plugins.announcements - ERROR - Could not fetch channel _blog from https://octoprint.org/feeds/octoblog.xml: HTTPSConnectionPool(host='octoprint.org', port=443): Max retries exceeded with url: /feeds/octoblog.xml (Caused by SSLError(SSLError(1, u'[SSL: CERTIFICATE_VERIFY_FAILED] certificate verify failed (_ssl.c:661)'),))
Traceback (most recent call last):
  File "/opt/octoprint/venv/lib/python2.7/site-packages/OctoPrint-1.3.6-py2.7.egg/octoprint/plugins/announcements/__init__.py", line 355, in _get_channel_data_from_network
    r = requests.get(url, timeout=30)
  File "/opt/octoprint/venv/lib/python2.7/site-packages/requests-2.18.4-py2.7.egg/requests/api.py", line 72, in get
    return request('get', url, params=params, **kwargs)
  File "/opt/octoprint/venv/lib/python2.7/site-packages/requests-2.18.4-py2.7.egg/requests/api.py", line 58, in request
    return session.request(method=method, url=url, **kwargs)
  File "/opt/octoprint/venv/lib/python2.7/site-packages/requests-2.18.4-py2.7.egg/requests/sessions.py", line 508, in request
    resp = self.send(prep, **send_kwargs)
  File "/opt/octoprint/venv/lib/python2.7/site-packages/requests-2.18.4-py2.7.egg/requests/sessions.py", line 618, in send
    r = adapter.send(request, **kwargs)
  File "/opt/octoprint/venv/lib/python2.7/site-packages/requests-2.18.4-py2.7.egg/requests/adapters.py", line 506, in send
    raise SSLError(e, request=request)
SSLError: HTTPSConnectionPool(host='octoprint.org', port=443): Max retries exceeded with url: /feeds/octoblog.xml (Caused by SSLError(SSLError(1, u'[SSL: CERTIFICATE_VERIFY_FAILED] certificate verify failed (_ssl.c:661)'),))
2021-11-15 21:35:07,139 - octoprint.plugins.announcements - ERROR - Could not fetch channel _plugins from https://plugins.octoprint.org/feed.xml: HTTPSConnectionPool(host='plugins.octoprint.org', port=443): Max retries exceeded with url: /feed.xml (Caused by SSLError(SSLError(1, u'[SSL: CERTIFICATE_VERIFY_FAILED] certificate verify failed (_ssl.c:661)'),))
Traceback (most recent call last):
  File "/opt/octoprint/venv/lib/python2.7/site-packages/OctoPrint-1.3.6-py2.7.egg/octoprint/plugins/announcements/__init__.py", line 355, in _get_channel_data_from_network
    r = requests.get(url, timeout=30)
  File "/opt/octoprint/venv/lib/python2.7/site-packages/requests-2.18.4-py2.7.egg/requests/api.py", line 72, in get
    return request('get', url, params=params, **kwargs)
  File "/opt/octoprint/venv/lib/python2.7/site-packages/requests-2.18.4-py2.7.egg/requests/api.py", line 58, in request
    return session.request(method=method, url=url, **kwargs)
  File "/opt/octoprint/venv/lib/python2.7/site-packages/requests-2.18.4-py2.7.egg/requests/sessions.py", line 508, in request
    resp = self.send(prep, **send_kwargs)
  File "/opt/octoprint/venv/lib/python2.7/site-packages/requests-2.18.4-py2.7.egg/requests/sessions.py", line 618, in send
    r = adapter.send(request, **kwargs)
  File "/opt/octoprint/venv/lib/python2.7/site-packages/requests-2.18.4-py2.7.egg/requests/adapters.py", line 506, in send
    raise SSLError(e, request=request)
SSLError: HTTPSConnectionPool(host='plugins.octoprint.org', port=443): Max retries exceeded with url: /feed.xml (Caused by SSLError(SSLError(1, u'[SSL: CERTIFICATE_VERIFY_FAILED] certificate verify failed (_ssl.c:661)'),))
2021-11-15 21:35:07,175 - octoprint.plugins.announcements - ERROR - Could not fetch channel _plugins from https://plugins.octoprint.org/feed.xml: HTTPSConnectionPool(host='plugins.octoprint.org', port=443): Max retries exceeded with url: /feed.xml (Caused by SSLError(SSLError(1, u'[SSL: CERTIFICATE_VERIFY_FAILED] certificate verify failed (_ssl.c:661)'),))
Traceback (most recent call last):
  File "/opt/octoprint/venv/lib/python2.7/site-packages/OctoPrint-1.3.6-py2.7.egg/octoprint/plugins/announcements/__init__.py", line 355, in _get_channel_data_from_network
    r = requests.get(url, timeout=30)
  File "/opt/octoprint/venv/lib/python2.7/site-packages/requests-2.18.4-py2.7.egg/requests/api.py", line 72, in get
    return request('get', url, params=params, **kwargs)
  File "/opt/octoprint/venv/lib/python2.7/site-packages/requests-2.18.4-py2.7.egg/requests/api.py", line 58, in request
    return session.request(method=method, url=url, **kwargs)
  File "/opt/octoprint/venv/lib/python2.7/site-packages/requests-2.18.4-py2.7.egg/requests/sessions.py", line 508, in request
    resp = self.send(prep, **send_kwargs)
  File "/opt/octoprint/venv/lib/python2.7/site-packages/requests-2.18.4-py2.7.egg/requests/sessions.py", line 618, in send
    r = adapter.send(request, **kwargs)
  File "/opt/octoprint/venv/lib/python2.7/site-packages/requests-2.18.4-py2.7.egg/requests/adapters.py", line 506, in send
    raise SSLError(e, request=request)
SSLError: HTTPSConnectionPool(host='plugins.octoprint.org', port=443): Max retries exceeded with url: /feed.xml (Caused by SSLError(SSLError(1, u'[SSL: CERTIFICATE_VERIFY_FAILED] certificate verify failed (_ssl.c:661)'),))
2021-11-15 21:35:07,216 - octoprint.plugins.announcements - ERROR - Could not fetch channel _octopi from https://octoprint.org/feeds/octopi.xml: HTTPSConnectionPool(host='octoprint.org', port=443): Max retries exceeded with url: /feeds/octopi.xml (Caused by SSLError(SSLError(1, u'[SSL: CERTIFICATE_VERIFY_FAILED] certificate verify failed (_ssl.c:661)'),))
Traceback (most recent call last):
  File "/opt/octoprint/venv/lib/python2.7/site-packages/OctoPrint-1.3.6-py2.7.egg/octoprint/plugins/announcements/__init__.py", line 355, in _get_channel_data_from_network
    r = requests.get(url, timeout=30)
  File "/opt/octoprint/venv/lib/python2.7/site-packages/requests-2.18.4-py2.7.egg/requests/api.py", line 72, in get
    return request('get', url, params=params, **kwargs)
  File "/opt/octoprint/venv/lib/python2.7/site-packages/requests-2.18.4-py2.7.egg/requests/api.py", line 58, in request
    return session.request(method=method, url=url, **kwargs)
  File "/opt/octoprint/venv/lib/python2.7/site-packages/requests-2.18.4-py2.7.egg/requests/sessions.py", line 508, in request
    resp = self.send(prep, **send_kwargs)
  File "/opt/octoprint/venv/lib/python2.7/site-packages/requests-2.18.4-py2.7.egg/requests/sessions.py", line 618, in send
    r = adapter.send(request, **kwargs)
  File "/opt/octoprint/venv/lib/python2.7/site-packages/requests-2.18.4-py2.7.egg/requests/adapters.py", line 506, in send
    raise SSLError(e, request=request)
SSLError: HTTPSConnectionPool(host='octoprint.org', port=443): Max retries exceeded with url: /feeds/octopi.xml (Caused by SSLError(SSLError(1, u'[SSL: CERTIFICATE_VERIFY_FAILED] certificate verify failed (_ssl.c:661)'),))
2021-11-15 21:35:07,245 - octoprint.plugins.announcements - ERROR - Could not fetch channel _octopi from https://octoprint.org/feeds/octopi.xml: HTTPSConnectionPool(host='octoprint.org', port=443): Max retries exceeded with url: /feeds/octopi.xml (Caused by SSLError(SSLError(1, u'[SSL: CERTIFICATE_VERIFY_FAILED] certificate verify failed (_ssl.c:661)'),))
Traceback (most recent call last):
  File "/opt/octoprint/venv/lib/python2.7/site-packages/OctoPrint-1.3.6-py2.7.egg/octoprint/plugins/announcements/__init__.py", line 355, in _get_channel_data_from_network
    r = requests.get(url, timeout=30)
  File "/opt/octoprint/venv/lib/python2.7/site-packages/requests-2.18.4-py2.7.egg/requests/api.py", line 72, in get
    return request('get', url, params=params, **kwargs)
  File "/opt/octoprint/venv/lib/python2.7/site-packages/requests-2.18.4-py2.7.egg/requests/api.py", line 58, in request
    return session.request(method=method, url=url, **kwargs)
  File "/opt/octoprint/venv/lib/python2.7/site-packages/requests-2.18.4-py2.7.egg/requests/sessions.py", line 508, in request
    resp = self.send(prep, **send_kwargs)
  File "/opt/octoprint/venv/lib/python2.7/site-packages/requests-2.18.4-py2.7.egg/requests/sessions.py", line 618, in send
    r = adapter.send(request, **kwargs)
  File "/opt/octoprint/venv/lib/python2.7/site-packages/requests-2.18.4-py2.7.egg/requests/adapters.py", line 506, in send
    raise SSLError(e, request=request)
SSLError: HTTPSConnectionPool(host='octoprint.org', port=443): Max retries exceeded with url: /feeds/octopi.xml (Caused by SSLError(SSLError(1, u'[SSL: CERTIFICATE_VERIFY_FAILED] certificate verify failed (_ssl.c:661)'),))
2021-11-15 21:35:07,421 - octoprint.plugins.softwareupdate - INFO - Saved version cache to disk
2021-11-15 21:35:07,423 - octoprint.plugins.softwareupdate - INFO - Saved version cache to disk
